Workbook

Sheet Eje 
A1: Simbolo | B1: Variable | C1: Valor | D1: Unidades
A2: P | B2: Potencia Intalada: | C2: 0.75 | D2: kW
C3: =C2*1000 -> 750 | D3: W
A4: N | B4: Velocidad: | C4: 90 | D4: rpm
C5: =C4/60 -> 1.5 | D5: rps
B7: Design for Strenght
A8: Tq(max) | B8: Torque máximo | C8: =C3/(2*PI()*C5) -> 79.577472 | D8: N.m
B10: Max Bending Moment
A11: Simbolo | B11: Variable | C11: Valor | D11: Unidades
A12: P1 calc | B12: Pot calc Propela 1 | C12: 308 | D12: W
A13: L1 | B13: Distancia prop 1 | C13: 2.5 | D13: m
A14: fH1 | B14: Factor hidraulico pop 1 | C14: 2 | D14: adim
A15: D1 | B15: Diámetro propela 1 | C15: 1 | D15: m
A16: P2 calc | B16: Pot calc Propela 2 | C16: 0 | D16: W
A17: L2 | B17: Distancia prop 2 | C17: 0 | D17: m
A18: fH2 | B18: Factor hidraulico pop 2 | C18: 0 | D18: adim
A19: D2 | B19: Diámetro propela 2 | C19: 1.2 | D19: m
A20: P3 calc | B20: Pot calc Propela 3 | C20: 0 | D20: W
A21: L3 | B21: Distancia prop 3 | C21: 0 | D21: m
A22: fH3 | B22: Factor hidraulico pop 3 | C22: 0 | D22: adim
A23: D3 | B23: Diámetro propela 3 | C23: 0.65 | D23: m
... A25: L4 | B25: Distancia prop 4 | C25: 0 | D25: m
A26: fH4 | B26: Factor hidraulico pop 4 | C26: =G85 -> 2
A27: D4 | B27: Diámetro propela 4 | C27: 1 | D27: m
A28: P1 | B28: Comp P total propela 1 | C28: =(C12/(C$12+C$16+C$20+C$24))*$C$3 -> 750 | D28: W
A29: P2 | B29: Comp P total propela 2 | C29: =(C16/(C$12+C$16+C$20+C$24))*$C$3 -> 0 | D29: W
A30: P3 | B30: Comp P total propela 3 | C30: =(C20/(C$12+C$16+C$20+C$24))*$C$3 -> 0 | D30: W
A31: P4 | B31: Comp P total propela 4 | C31: =(C24/(C$12+C$16+C$20+C$24))*$C$3 -> 0 | D31: W
A32: M1 | B32: Componente P1 del M max | C32: =0.048*C28*C13*C14/(C15*$C$5) -> 120 | D32: N.m
A33: M2 | B33: Componente P2 del M max | C33: =0.048*C29*C17*C18/(C19*$C$5) -> 0 | D33: N.m
A34: M3 | B34: Componente P3 del M max | C34: =0.048*C28*C21*C22/(C23*$C$5) -> 0 | D34: N.m
A35: M4 | B35: Componente P4 del M max | C35: =0.048*C31*C26*C25/(C27*$C$5) -> 0 | D35: N.m
A36: Mmax | B36: Max Bending Moment | C36: =SUM(C32:C35) -> 120 | D36: N.m
A39: Calculo del diámetro de eje mínimo shear stress(barra)
A40: Simbolo | B40: Variable | C40: Valor | D40: Unidades
B41: Material del eje | C41: 316SS
A42: Ơs | B42: Shear stress limit | C42: =41400000 -> 41400000 | D42: N/m2
A43: TQ max | B43: Torque max | C43: =C$8 -> 79.577472 | D43: N.m
A44: Mmax | B44: Max Bending Moment | C44: =C$36 -> 120 | D44: N.m
A45: ds | B45: Diametro min | C45: =POWER((16*POWER(C43^2+C44^2,1/2)/(PI()*C42)),1/3) -> 0.026067465 | D45: m
...

Sheet Potencia
B3: Cálculo de Reynolds
B4: Símbolo | C4: Variable | D4: Valor | E4: Unidades
B5: ρ | C5: Densidad | D5: 900 | E5: kg/m3
B6: D | C6: Diámetro propela | D6: 1.2 | E6: m
B7: N | C7: Velocidad de rotación | D7: =120/60 -> 2 | E7: rps
B8: μ | C8: Viscosidad | D8: 600 | E8: cP
D9: =D8/1000 -> 0.6 | E9: Pa.s
C10: Velocidad tangencial | D10: =PI()*D6*D7 -> 7.5398224 | E10: m/s
B11: Re | C11: Reynolds | D11: =D7*D6*D6*D5/D9 -> 4320 | E11: adimen
B12: Re2 | C12: Reynolds libro | D12: =D5*D6*D10/D9 -> 13571.68
B16: Calculo del Np- a partir de lo calculado por el selector
B17: Simbolo | C17: Variable | D17: Valor | E17: Unidades
B18: Pct | C18: Potencia calculada, antes de selecciónar el motor | D18: 10.4 | E18: kW
D19: =1000*D18 -> 10400 | E19: W
C20: Potencia cálculada antes de Bafles | D20: =D19/1.4 -> 7428.5714 | E20: W
C21: Potencia cálculada antes de Fs | D21: =D20/1.3 -> 5714.2857 | E21: W
B22: c_p | C22: Cantidad de Propelas | D22: 2
B23: P | C23: P calc por propela | D23: =D21/D22 -> 2857.1429 | E23: W
C25: Diametro propela | D25: 1.2 | E25: m
C26: Densidad | D26: 900 | E26: kg/m3
C27: Velocidad de rotación | D27: 2 | E27: rps
B28: Np | C28: Número de Potencia | D28: =D23/(D26*D27^3*D25^5) -> 0.15947523 | E28: adms
D30: 2.31
B34: Cálculo de Potencia por Propela
B35: Símbolo | C35: Variable | D35: Valor | E35: Unidades
B36: Po/Np | C36: Número de Potencia | D36: 0.16 | E36: adimen
B37: D | C37: Diámetro propela | D37: 1.2 | E37: m
B38: ρ | C38: Densidad | D38: 900 | E38: kg/m3
B39: N | C39: Velocidad de rotación | D39: 2 | E39: rps
B40: P | C40: Potencia | D40: =D36*D38*D39^3*D37^5 -> 2866.5446 | E40: W
D41: =D40/1000 -> 2.8665446 | E41: kW
D46: =D41*2 -> 5.7330893
D47: =D46*1.4 -> 8.026325
D48: =D47*1.3 -> 10.434222

Sheet Vel vs Torque
B2: Frecuencia (hz) | C2: Velocidad (rpm) | D2: Potencia max(kW) | E2: Torque (N.m)
B3: 60 | C3: 120 | D3: 11 | E3: =('Vel vs Torque'!D3*1000)/(2*PI()*('Vel vs Torque'!C3/60)) -> 875.35219
B4: 50 | C4: =($C$3/$B$3)*B4 -> 100 | D4: 11 | E4: =('Vel vs Torque'!D4*1000)/(2*PI()*('Vel vs Torque'!C4/60)) -> 1050.4226
B5: 40 | C5: =($C$3/$B$3)*B5 -> 80 | D5: 11 | E5: =('Vel vs Torque'!D5*1000)/(2*PI()*('Vel vs Torque'!C5/60)) -> 1313.0283
B6: 30 | C6: =($C$3/$B$3)*B6 -> 60 | D6: 11 | E6: =('Vel vs Torque'!D6*1000)/(2*PI()*('Vel vs Torque'!C6/60)) -> 1750.7044
B7: 20 | C7: =($C$3/$B$3)*B7 -> 40 | D7: 11 | E7: =('Vel vs Torque'!D7*1000)/(2*PI()*('Vel vs Torque'!C7/60)) -> 2626.0566
B8: 15 | C8: =($C$3/$B$3)*B8 -> 30 | D8: 11 | E8: =('Vel vs Torque'!D8*1000)/(2*PI()*('Vel vs Torque'!C8/60)) -> 3501.4087
B13: Frecuencia (hz) | C13: Velocidad (rpm) | D13: Potencia teorica consumida (kW) | E13: Torque (N.m)
B14: 60 | C14: 120 | D14: =10.4/1.3 -> 8 | E14: =('Vel vs Torque'!D14*1000)/(2*PI()*('Vel vs Torque'!C14/60)) -> 636.61977
B15: 50 | C15: =($C$3/$B$3)*B15 -> 100 | D15: =6.02/1.3 -> 4.6307692 | E15: =('Vel vs Torque'!D15*1000)/(2*PI()*('Vel vs Torque'!C15/60)) -> 442.20589
B16: 40 | C16: =($C$3/$B$3)*B16 -> 80 | D16: =3.08/1.2 -> 2.5666667 | E16: =('Vel vs Torque'!D16*1000)/(2*PI()*('Vel vs Torque'!C16/60)) -> 306.37327
B17: 30 | C17: =($C$3/$B$3)*B17 -> 60 | D17: =1.3/1.2 -> 1.0833333 | E17: =('Vel vs Torque'!D17*1000)/(2*PI()*('Vel vs Torque'!C17/60)) -> 172.41786
B18: 20 | C18: =($C$3/$B$3)*B18 -> 40 | D18: =0.39/1.3 -> 0.3 | E18: =('Vel vs Torque'!D18*1000)/(2*PI()*('Vel vs Torque'!C18/60)) -> 71.619724
B19: 15 | C19: =($C$3/$B$3)*B19 -> 30 | D19: =0.16/1.3 -> 0.12307692 | E19: =('Vel vs Torque'!D19*1000)/(2*PI()*('Vel vs Torque'!C19/60)) -> 39.176601

Sheet Fondo Flanged Dished
A3: De: | B3: 3000
A4: e: | B4: 10
A5: h1: | B5: 7
A6: Di: | B6: =B3-(2*B4) -> 2980
A7: R: | B7: =B3 -> 3000
A8: r: | B8: =0.06*B3 -> 180
A9: h2: | B9: =B7-SQRT(POWER(B7-B8,2)-POWER(B6/2-B8,2)) -> 502.7415
A10: H: | B10: =B9+B4+B5 -> 519.7415
A11: V: | B11: =POWER((B6/25.4),3)*0.0013 -> 2099.3797
A15: Volumen cil | B15: =(B6*B6*PI()*B9/4)/1000000000 -> 3.5064459 | C15: m3
B16: =B15*1000 -> 3506.4459 | C16: L
B17: =B11/B16 -> 0.59872011

Sheet Fondo Klopper
A3: De: | B3: 3000
A4: e: | B4: 10
A5: h1: | B5: =3.5*B4 -> 35
A6: Di: | B6: =B3-(2*B4) -> 2980
A7: R: | B7: =B3 -> 3000
A8: r: | B8: =B3/10 -> 300
A9: h2: | B9: =0.1935*B3-0.455*B4 -> 575.95 | C9: 576
A10: H: | B10: =B9+B4+B5 -> 620.95
A11: V: | B11: =POWER(B6/1000,3)*0.1 -> 2.6463592 | C11: m3
A12: V: | B12: =B11*1000 -> 2646.3592 | C12: L
A15: Volumen cil | B15: =(B6*B6*PI()*B9/4)/1000000000 -> 4.0170496
B16: =B15*1000 -> 4017.0496
B17: =B12/B16 -> 0.65878181

Sheet Fondo 
A3: De: | B3: 3000
A4: e: | B4: 10
A5: h1: | B5: 50
A6: Di: | B6: =B3-(2*B4) -> 2980
A7: R: | B7: 3656
A8: r: | B8: 50
A9: h2: | B9: =B7-SQRT((B7-B8)^2-(B6/2-B8)^2) -> 350
A10: H: | B10: =B9+B4+B5 -> 410
A11: V: | B11: =POWER((B6)+0.2,2)*0.455*(B9)/1000000000 -> 1.4143935 | C11: m3
A12: V: | B12: =B11*1000 -> 1414.3935 | C12: L
A15: Volumen cil | B15: =(B6*B6*PI()*B9/4)/1000000000 -> 2.4411275
B16: =B15*1000 -> 2441.1275
B17: =B12/B16 -> 0.57940176

Sheet Nivel del Tanque
A1: Diámetro de Propela | B1: 1200 | C1: mm
A2: Diámetro de Tanque | B2: 3000 | C2: mm
A3: Altura tota tanque | B3: 4016
A4: Volumen nominal tanque | B4: 25 | C4: m3
A6: Altura boquilla (aprox) | B6: 200
A7: Distancia total borde conexión a fondo | B7: =B3+B6 -> 4216
A8: Agitador de boquilla a parte inferior | B8: 3180
A9: Distancia a fondo | B9: =B7-B8-36 -> 1000
A10: Porcentaje con relación al borde | B10: =B9/B1 -> 0.83333333
A13: Altura de sumergencia | B13: 200
A14: Altura de línea de agua al fondo | B14: =B9+B13 -> 1200
A16: Altura de parte curva | B16: =350 -> 350
A17: Altura parte cilindrica | B17: =B14-B16 -> 850
A19: Volumen fondo curvo | B19: ='Fondo '!B11 -> 1.4143935 | C19: m3
A20: Volumen parte cilindrica | B20: =(B17/1000)*(B2/1000)^2*PI()/4 -> 6.0082959 | C20: m3
A21: Volumen mínimo recomendado | B21: =B19+B20 -> 7.4226895 | C21: m3
A22: Porcentaje de nivel mínimo | B22: =B21/B4 -> 0.29690758
