Workbook
Name ACOPLE_BRIDADO: 'P. PARTES'!$A$266:$A$322
Name ACOPLE_DIRECTO: 'P. PARTES'!$A$239:$A$263
Name EJE_MACIZO: 'P. PARTES'!$A$325:$A$376
Name EJE_TUBULAR: 'P. PARTES'!$A$379:$A$434
Name MOTOREDUCTOR: 'P. PARTES'!$A$457:$A$563
Name NO_APLICA: 'P. PARTES'!$E$607:$E$612
Name PERNOS: 'P. PARTES'!$A$566:$A$568
Name PLACA: 'P. PARTES'!$A$571
Name PLETINAS: 'P. PARTES'!$A$437:$A$454
Name PROPELAS: 'P. PARTES'!$A$3:$A$236

Sheet CODIFICADOR
A1: CODIFICACION DE PARTES DE AGITADOR
G3: P3-LICS
A4: CODIFICACION EJE
A6: SELECCIONAR TIPO DE ACOPLE | B6: SELECCIONAR SCHEDULE | C6: ESCRIBA LONGITUD EN mm | D6: SELECCIONAR DIAMETRO | E6: SELECCIONAR MATERIAL | G6: CODIGO
A7: BRIDADO | B7: MACIZO | C7: 1700 | D7: (2") | E7: Acero 316SS | G7: =CONCATENATE("EJ",VLOOKUP(A7,'HERR CODS'!C2:D3,2,0),VLOOKUP(B7,'HERR CODS'!E2:F5,2,0),IF(C7/10<100,CONCATENATE("0",C7/10),C7/10),VLOOKUP(D7,'HERR CODS'!I2:J14,2,0),VLOOKUP(E7,'HERR CODS'!K2:L4,2,0)) -> EJBA170ES
G8: =IF(COUNTIF('P. PARTES'!$A$4:$C$604,CODIFICADOR!G7)=1,"SI","NO") -> NO
A10: CODIFICACION ACOPLE BRIDADO
G11: CODIGO
A12: SELECCIONAR DIAMETRO DE AGITADOR | B12: SELECCIONAR DIAMETRO DE EJE MOTOREDUCTOR (mm) | C12: SELECCIONAR MATERIAL | G12: =CONCATENATE("AB-",VLOOKUP(A13,'HERR CODS'!B24:C29,2,0),"-",VLOOKUP(B13,'HERR CODS'!P24:Q36,2,0),VLOOKUP(C13,'HERR CODS'!H70:I74,2,0)) -> AB-2-30
A13: 2" | B13: 30 | C13: ACERO 304SS | G13: =IF(COUNTIF('P. PARTES'!$A$4:$C$604,CODIFICADOR!G12)=1,"SI","NO") -> SI
A16: CODIFICACION ACOPLE DIRECTO
G17: CODIGO
A18: SELECCIONAR DIAMETRO DE EJE MOTOREDUCTOR (mm) | B18: SELECCIONAR DIAMETRO DE AGITADOR | C18: SELECCIONAR MATERIAL | G18: =CONCATENATE("AD-",VLOOKUP(A19,'HERR CODS'!E24:F36,2,0),"-",VLOOKUP(B19,'HERR CODS'!B72:C75,2,0),VLOOKUP(C19,'HERR CODS'!H70:I74,2,0)) -> #N/A
G19: EXISTE?
G20: =IF(COUNTIF('P. PARTES'!$A$4:$C$604,CODIFICADOR!G18)=1,"SI","NO") -> NO
A22: CODIFICACION PROPELA
G23: CODIGO
A24: SELECCIONAR TIPO DE PROPELA | B24: SELECCIONAR DIAMETRO DE PROPELA (mm) | C24: SELECCIONAR DIAMETRO DE EJE | D24: SELECCIONAR TIPO DE AJUSTE AL EJE | E24: SELECCIONAR MATERIAL | G24: =CONCATENATE("P",VLOOKUP(A25,'HERR CODS'!A40:B49,2,0),"-",VLOOKUP(B25,'HERR CODS'!D40:E64,2,0),VLOOKUP(C25,'HERR CODS'!G40:H53,2,0),VLOOKUP(D25,'HERR CODS'!I40:J42,2,0),VLOOKUP(E25,'HERR CODS'!M40:N42,2,0)) -> P2-GEMS
A25: TURBINA | B25: 500 | C25: (2") | D25: MANZANA | E25: Acero inoxidable 316SS | G25: EXISTE?
G26: =IF(COUNTIF('P. PARTES'!$A$3:$C$604,CODIFICADOR!G24)=1,"SI","NO") -> SI
A29: CODIFICACION AGITADOR
B31: PROPELA TIPO 1 (DE ABAJO HACIA ARRIBA)
A32: SELECCIONAR TIPO | B32: TIPO DE PROPELAS | C32: NÚMERO DE PROPELAS | D32: DIAMETRO (mm)
A33: VERTICAL | B33: CURVA TRIPALA - CT | C33: 1 | D33: 500
B35: PROPELA TIPO 2 (DE ARRIBA HACIA ABAJO)
B36: TIPO DE PROPELAS | C36: NÚMERO DE PROPELAS | D36: DIAMETRO
B37: NO APLICA | C37: NO APLICA | D37: NO APLICA | G37: CODIGO
G38: =CONCATENATE(VLOOKUP(A33,'HERR CODS'!A83:B84,2,0),VLOOKUP(B33,'HERR CODS'!C91:D101,2,0),VLOOKUP(C33,'HERR CODS'!E92:F96,2,0),VLOOKUP(D33,'HERR CODS'!G102:H128,2,0),VLOOKUP(B37,'HERR CODS'!C91:D101,2,0),IF(B37="NO APLICA",,VLOOKUP(C37,'HERR CODS'!E92:F96,2,0)),IF(B37="NO APLICA","-",VLOOKUP(D37,'HERR CODS'!G102:H128,2,0)),IF(B40/100<10,CONCATENATE("0",B40/100),B40/100),VLOOKUP(C40,'HERR CODS'!Q103:R124,2,0),IF(D40<100,CONCATENATE("0",D40),D40),VLOOKUP(B44,'HERR CODS'!U90:V91,2,0),VLOOKUP(C44,'HERR CODS'!W90:X95,2,0),VLOOKUP(CODIFICADOR!D44,'HERR CODS'!Y90:Z91,2,0),VLOOKUP(CODIFICADOR!B46,'HERR CODS'!AA90:AB91,2,0),VLOOKUP(CODIFICADOR!C46,'HERR CODS'!AC90:AD93,2,0),VLOOKUP(D46,'HERR CODS'!AE89:AF95,2,0)) -> V3AF-08G090 | AI38: =CONCATENATE(VLOOKUP(AC33,'HERR CODS'!AC83:AD84,2,0),VLOOKUP(AD33,'HERR CODS'!AE91:AF101,2,0),VLOOKUP(AE33,'HERR CODS'!AG92:AH96,2,0),VLOOKUP(AF33,'HERR CODS'!AI102:AJ128,2,0),VLOOKUP(AD37,'HERR CODS'!AE91:AF101,2,0),IF(AD37="NO APLICA",,VLOOKUP(AE37,'HERR CODS'!AG92:AH96,2,0)),IF(AD37="NO APLICA","-",VLOOKUP(AF37,'HERR CODS'!AI102:AJ128,2,0)),IF(AD40/100<10,CONCATENATE("0",AD40/100),AD40/100),VLOOKUP(AE40,'HERR CODS'!AS103:AT124,2,0),IF(AF40<100,CONCATENATE("0",AF40),AF40),VLOOKUP(AD44,'HERR CODS'!AW90:AX91,2,0),VLOOKUP(AE44,'HERR CODS'!AY90:AZ95,2,0),VLOOKUP(CODIFICADOR!AF44,'HERR CODS'!BA90:BB91,2,0),VLOOKUP(CODIFICADOR!AD46,'HERR CODS'!BC90:BD91,2,0),VLOOKUP(CODIFICADOR!AE46,'HERR CODS'!BE90:BF93,2,0),VLOOKUP(AF46,'HERR CODS'!BG89:BH94,2,0)) -> #N/A
B39: ESCRIBA LONGITUD EJE EN mm | C39: POTENCIA (Kw) | D39: ESCRIBA VELOCIDAD (rpm)
B40: 800 | C40: 2.2 | D40: 90
B42: ADICIONALES
B43: MANEJO VELOCIDAD | C43: ELEMENTO MOTRIZ | D43: LINTERNA
B44: VELOCIDAD REDUCIDA | C44: TRIFASICO | D44: Sin linterna
B45: SELLO | C45: MATERIAL | D45: ACABADO - RECUBRIMIENTO
B46: Sin sello | C46: 304SS | D46: NINGUNO
D56: =2.44/3 -> 0.81333333

Sheet PLANTILLA DE P.  (2)
I1: NOTAS DE SELECCIÓN
A2: MODELO DEL AGITADOR: | E2: FECHA | G2: ELABORO
B4: CÓDIGO | C4: DESCRIPCIÓN PIEZA | D4: CANT | G4: VALOR PARCIAL
A5: MOTOREDUCTOR | B5: SK5721IEC90SK90L4 | C5: MOTORREDUTOR 2.2 KW // 90 RPM//SK5721IEC100C20 | D5: 1 | E5: 5378000 | G5: =E5 -> 5378000 | H5: NORD | Q5: =NOT(R5) -> FALSE | R5: =COUNTIF(INDIRECT(A5),B5) -> 1
C6: LITERNA DE RODAMIENTOS | D6: 0 | E6: 9000000 | G6: =E6*D6 -> 0
A7: PROPELAS | B7: P3-GDC | C7: =VLOOKUP(B7,'P. PARTES'!$A$3:C689,3,0) -> Propela Tripala 500 mm eje 1 1/2" con casquete 304SS | D7: 1 | E7: 700000 | G7: =E7*D7 -> 700000
A8: ACOPLE_DIRECTO | B8: AD-025-038 | C8: =VLOOKUP(B8,'P. PARTES'!$A$3:C689,3,0) -> Acople directo EJE AG 1 1/2" EJE MR 25 mm 304SS | D8: 1 | E8: 380000 | G8: =E8*D8 -> 380000
A9: EJE_MACIZO | B9: EJDA100D | C9: =VLOOKUP(B9,'P. PARTES'!$A$3:C690,3,0) -> Eje macizo 1 1/2" 500 - 1000 mm 304SS | D9: 1 | E9: 400000 | G9: =E9*D9 -> 400000 | I9: Sujeta a cambios dependiendo el tamaño del eje del MR | Q9: =NOT(R9) -> FALSE | R9: =COUNTIF(INDIRECT(A9),B9) -> 1
A10: PLETINAS | B10: PL-210-516-110 | C10: =VLOOKUP(B10,'P. PARTES'!$A$3:C691,3,0) -> Pletina cuadrada de 210 mm * 5/16" A36 GALVANIZADO | D10: 1 | E10: 250000 | G10: =E10*D10 -> 250000 | Q10: =NOT(R10) -> FALSE | R10: =COUNTIF(INDIRECT(A10),B10) -> 1
A11: PERNOS | B11: PERNOS AG PEQUEÑO | C11: Para | D11: 1 | E11: 20000 | G11: =E11*D11 -> 20000 | Q11: =NOT(R11) -> FALSE | R11: =COUNTIF(INDIRECT(A11),B11) -> 1
A12: PLACA | B12: PLACAS AG. | C12: PLACA | D12: 1 | E12: 52000 | G12: =E12*D12 -> 52000 | Q12: =NOT(R12) -> FALSE | R12: =COUNTIF(INDIRECT(A12),B12) -> 1
A13: OTROS | C13: EMPAQUE (MADERA) | D13: 1 | E13: 150000 | G13: =E13*D13 -> 150000 | Q13: =NOT(R13) -> #REF! | R13: =COUNTIF(INDIRECT(A13),B13) -> #REF!
A14: OTROS | C14: EMPAQUE (MANO DE OBRA) | D14: 1 | E14: 150000 | G14: =E14*D14 -> 150000
A15: OTROS | C15: PRUEBAS y DOCUMENTACION | D15: 0 | E15: 300000 | G15: =E15*D15 -> 0
A16: OTROS | C16: PINTURA | D16: 0 | E16: 200000 | G16: =E16*D16 -> 0 | M16: MARGEN | Q16: =NOT(R16) -> #REF! | R16: =COUNTIF(INDIRECT(A16),B16) -> #REF!
A17: OTROS | B17: OTROS | C17: RECUBRIMIENTO | D17: 0 | E17: 8000000 | G17: =E17*D17 -> 0
A18: OTROS | B18: OTROS | C18: ACOMPAÑAMIENTO EN ARRANQUE Y PRUEBAS | D18: 1 | E18: 2300000 | G18: =E18*D18 -> 2300000
D19: Subtotal materiales | G19: =SUM(G5:G18) -> 9780000 | K19: =G23/L19 -> 21750720 | L19: 0.5 | M19: 0.5
A20: DÓLAR | B20: 3650 | D20: Imprevistos | F20: 0.05 | G20: =G19*F20 -> 489000 | K20: =K19/B20 -> 5959.1014 | L20: 4000
D21: Gastos administrativos | F21: 0.05 | G21: =(G19*F21) -> 489000 | H21: T.PAGO/MESES
D22: Gastos financieros | F22: 0.012 | G22: =G19*F22*H22 -> 117360 | H22: 1
D23: Subtotal | G23: =SUM(G19:G22) -> 10875360
D24: Margen | F24: 0.4 | G24: =G23*F24 -> 4350144 | K24: 15300 | L24: usd
D25: Total COP | G25: =G23+G24 -> 15225504 | J25: =#REF!*I25 -> #REF!
D26: Total USD | G26: =G25/B20 -> 4171.371
D27: Valor de venta COP | G27: =ROUND(G25,-4) -> 15230000
D28: Valor de venta USD | G28: =ROUND(G26,-1) -> 4170
L30: 2023 | N30: INCREMENTO
L31: =K19 -> 21750720 | M31: COP | N31: =(L31-K31)/K31 -> #DIV/0!
L32: =K24 -> 15300 | M32: USD | N32: =(L32-K32)/K32 -> #DIV/0!
AF38: SI | AH38: 1
AF39: NO | AH39: 1.19
C76: MARGEN GLOBAL BASE MATERIALES
C77: =(G24+#REF!+#REF!+#REF!)/#REF! -> #REF!

Sheet Hoja1
A1: PROPELA P5-SGC
B2: Descripción | C2: Área m2 | D2: Cantidad | E2: Área total | F2: Material | G2: Peso kg | H2: Costo por kg | I2: 35000
A3: LÁMINAS | B3: Ruana | C3: =(106/1000*160/1000) -> 0.01696 | D3: 2 | E3: =D3*C3 -> 0.03392 | F3: 304ss
B4: Casquete plano | C4: =91/1000*300/1000 -> 0.0273 | D4: 4 | E4: =D4*C4 -> 0.1092 | F4: 304ss
B5: Casquete curvo | C5: =(300/1000*182/1000) -> 0.0546 | D5: 2 | E5: =D5*C5 -> 0.1092 | F5: 304ss
B6: Atiezador | C6: =(530/1000*24/1000) -> 0.01272 | D6: 2 | E6: =D6*C6 -> 0.02544 | F6: 304ss
B7: Aspa | C7: =(770/1000*270/1000) -> 0.2079 | D7: 2 | E7: =D7*C7 -> 0.4158 | F7: 304ss
D8: Área total m2 | E8: =SUM(E3:E7) -> 0.69356 | F8: 304ss
D9: Peso total kg | G9: 44.35
D10: Costo total COP | H10: =I2*G9 -> 1552250
A13: SERVICIO | B13: 990000
A15: COSTO PROPELA | B15: =H10+B13 -> 2542250

Sheet V2
A1: V2AB-06A137 | E1: V2AI-16E072 | I1: V2AI-24H108
A2: Elemento | B2: Precio | C2: PESO (KG) | E2: Elemento | F2: Precio | G2: PESO (KG) | I2: Elemento | J2: Precio | K2: PESO (KG)
A3: MR 0.25kW @ 140,4 RPM SK0721IEC71SK71S4 | B3: =INSUMOS!B524 -> 850000 | C3: =INSUMOS!E524 -> 9 | E3: MR 1,1kW @ 72 RPM SK5721IEC90SK90S4 | F3: =INSUMOS!B526 -> 1400000 | G3: =INSUMOS!E527 -> 29 | I3: MR 3kW @ 108RPM SK7721IEC100SK100LA4 | J3: =INSUMOS!B529 -> 2260000 | K3: =INSUMOS!E529 -> 87
A4: Pletina 210 * 1/4" | B4: =INSUMOS!B112 -> 96000 | C4: =INSUMOS!E112 -> 2.1982747 | E4: Pletina 210 * 1/4" | F4: =INSUMOS!B112 -> 96000 | G4: =INSUMOS!E112 -> 2.1982747 | I4: Pletina 350 * 1/4" | J4: =INSUMOS!B117 -> 115000 | K4: =INSUMOS!E117 -> 6.1063187
A5: EJE EJDA065B | B5: =EJXA!D5 -> 85350 | C5: =EJXA!E5 -> 2.5854749 | E5: EJE EJDA160E | F5: =EJXA!D33 -> 323400 | G5: =EJXA!E33 -> 25.456984 | I5: EJE EJBC240G | J5: =EJXC!D6 -> 1711923 | K5: =EJXC!E6 -> 32.05
A6: ACOPLE AD-020-025 | B6: =AD!D5 -> 197400 | C6: =AD!E5 -> 1.7899442 | E6: ACOPLE AD-035-050 | F6: =AD!D25 -> 358200 | G6: =AD!E39 -> 7.1597767 | I6: ACOPLE AB-3-040 | J6: =AB!D27 -> 546265 | K6: =AB!E27 -> 9.0468716
A7: PROPELA P2-BBM | B7: =P!D8 -> 391250 | C7: =P!E8 -> 2.3124581 | E7: PROPELA P2-JEM | F7: =P!D128 -> 779150 | G7: =P!E128 -> 21.999833 | I7: PROPELA P2-JGC | J7: =P!D157 -> 770000 | K7: =P!E157 -> 22.63
A8: PLACAS | B8: =INSUMOS!B537 -> 50000 | E8: PLACAS | F8: =INSUMOS!B537 -> 50000 | I8: PLACAS | J8: =INSUMOS!B537 -> 50000
A9: TORNILLOS AG PEQUEÑO | B9: =INSUMOS!B534 -> 50000 | C9: =INSUMOS!E534 -> 3 | E9: TORNILLOS AG MEDIANO | F9: =INSUMOS!B535 -> 80000 | G9: =INSUMOS!E535 -> 5 | I9: TORNILLOS AG MEDIANO | J9: =INSUMOS!B535 -> 80000 | K9: =INSUMOS!E535 -> 5
A10: TOTAL MATERIALES | B10: =SUM(B3:B9) -> 1720000 | C10: =SUM(C3:C9) -> 20.886152 | E10: TOTAL MATERIALES | F10: =SUM(F3:F9) -> 3086750 | G10: =SUM(G3:G9) -> 90.814868 | I10: TOTAL MATERIALES | J10: =SUM(J3:J9) -> 5533188 | K10: =SUM(K3:K9) -> 161.83319
A12: V2AD-09A137 | E12: V2AI-18F077 | I12: V2AJ-24H088
A13: Elemento | B13: Precio | C13: PESO (KG) | E13: Elemento | F13: Precio | G13: PESO (KG) | I13: Elemento | J13: Precio | K13: PESO (KG)
A14: MR 0.25kW @ 140,4 RPM SK0721IEC71SK71S4 | B14: =INSUMOS!B524 -> 850000 | C14: =INSUMOS!E524 -> 9 | E14: MR 1,5kW @ 76,8 RPM SK5721IEC90SK90L4 | F14: =INSUMOS!B527 -> 1410000 | G14: =INSUMOS!E526 -> 29 | I14: MR 3kW @ 88RPM SK7721IEC100SK100LA4 | J14: =INSUMOS!B529 -> 2260000 | K14: =INSUMOS!E529 -> 87
A15: Pletina 210 * 1/4" | B15: =INSUMOS!B112 -> 96000 | C15: =INSUMOS!E112 -> 2.1982747 | E15: Pletina 210 * 1/4" | F15: =INSUMOS!B112 -> 96000 | G15: =INSUMOS!E112 -> 2.1982747 | I15: Pletina 350 * 1/4" | J15: =INSUMOS!B117 -> 115000 | K15: =INSUMOS!E117 -> 6.1063187
A16: EJE EJDA090B | B16: =EJXA!D12 -> 95100 | C16: =EJXA!E12 -> 3.5798883 | E16: EJE EJDA180E | F16: =EJXA!D46 -> 354200 | G16: =EJXA!E46 -> 28.639107 | I16: EJE EJBC240G | J16: =EJXC!D6 -> 1711923 | K16: =EJXC!E6 -> 32.05
A17: ACOPLE AD-020-025 | B17: =AD!D5 -> 197400 | C17: =AD!E5 -> 1.7899442 | E17: ACOPLE AD-035-050 | F17: =AD!D25 -> 358200 | G17: =AD!E39 -> 7.1597767 | I17: ACOPLE AB-3-040 | J17: =AB!D27 -> 546265 | K17: =AB!E27 -> 9.0468716
A18: PROPELA P2-DBM | B18: =P!D18 -> 441250 | C18: =P!E18 -> 4.2524581 | E18: PROPELA P2-JEM | F18: =P!D128 -> 779150 | G18: =P!E128 -> 21.999833 | I18: PROPELA P2-kGC | J18: =P!D166 -> 850000 | K18: =P!E166 -> 30
A19: PLACAS | B19: =INSUMOS!B537 -> 50000 | E19: PLACAS | F19: =INSUMOS!B537 -> 50000 | I19: PLACAS | J19: =INSUMOS!B537 -> 50000
A20: TORNILLOS AG PEQUEÑO | B20: =INSUMOS!B534 -> 50000 | C20: =INSUMOS!E534 -> 3 | E20: TORNILLOS AG MEDIANO | F20: =INSUMOS!B535 -> 80000 | G20: =INSUMOS!E535 -> 5 | I20: TORNILLOS AG MEDIANO | J20: =INSUMOS!B535 -> 80000 | K20: =INSUMOS!E535 -> 5
A21: TOTAL | B21: =SUM(B14:B20) -> 1779750 | C21: =SUM(C14:C20) -> 23.820565 | E21: TOTAL MATERIALES | F21: =SUM(F14:F20) -> 3127550 | G21: =SUM(G14:G20) -> 93.996991 | I21: TOTAL MATERIALES | J21: =SUM(J14:J20) -> 5613188 | K21: =SUM(K14:K20) -> 169.20319
A23: V2AD-11C192 | E23: V2AJ-20B046 | I23: V2AJ-26J102
A24: Elemento | B24: Precio | C24: PESO (KG) | E24: Elemento | F24: Precio | G24: PESO (KG) | I24: Elemento | J24: Precio | K24: PESO (KG)
A25: MR 0.55kW @ 190 RPM SK1721IEC80SK80S4 | B25: =INSUMOS!B525 -> 1100000 | C25: =INSUMOS!E525 -> 13 | E25: MR 0,37kW @ 46RPM SK3721IEC71SK71L4 | F25: =INSUMOS!B528 -> 1040000 | G25: =INSUMOS!E528 -> 28 | I25: MR 5,5kW @ 102RPM SK8721IEC132SK132S4 | J25: =INSUMOS!B530 -> 4900000 | K25: =INSUMOS!E530 -> 97
A26: Pletina 210 * 1/4" | B26: =INSUMOS!B112 -> 96000 | C26: =INSUMOS!E112 -> 2.1982747 | E26: Pletina 210 * 1/4" | F26: =INSUMOS!B112 -> 96000 | G26: =INSUMOS!E112 -> 2.1982747 | I26: Pletina 350 * 3/8" | J26: =INSUMOS!B118 -> 160000 | K26: =INSUMOS!E118 -> 9.1594781
A27: EJE EJDA109C | B27: =EJXA!D19 -> 129760 | C27: =EJXA!E19 -> 6.7744415 | E27: EJE EJDA200D | F27: =EJXA!D53 -> 251000 | G27: =EJXA!E53 -> 17.899442 | I27: EJE EJBC270I | J27: =EJXC!D13 -> 2618025 | K27: =EJXC!E13 -> 50.443
A28: ACOPLE AD-020-032 | B28: =AD!D12 -> 232800 | C28: =AD!E12 -> 3.182123 | E28: ACOPLE AD-025-038 | F28: =AD!D32 -> 232800 | G28: =AD!E32 -> 3.182123 | I28: ACOPLE AB-4-050 | J28: =AB!D13 -> 647320 | K28: =AB!E13 -> 15.909944
A29: PROPELA P2-DCM | B29: =P!D28 -> 473100 | C29: =P!E28 -> 5.2965922 | E29: PROPELA P2-KDM | F29: =P!D138 -> 763100 | G29: =P!E138 -> 26.386592 | I29: PROPELA P2-KIC | J29: =P!D176 -> 880000 | K29: =P!E176 -> 32
A30: PLACAS | B30: =INSUMOS!B537 -> 50000 | E30: PLACAS | F30: =INSUMOS!B537 -> 50000 | I30: PLACAS | J30: =INSUMOS!B537 -> 50000
A31: TORNILLOS AG PEQUEÑO | B31: =INSUMOS!B534 -> 50000 | C31: =INSUMOS!E534 -> 3 | E31: TORNILLOS AG MEDIANO | F31: =INSUMOS!B535 -> 80000 | G31: =INSUMOS!E535 -> 5 | I31: TORNILLOS AG MEDIANO | J31: =INSUMOS!B535 -> 80000 | K31: =INSUMOS!E535 -> 5
A32: TOTAL | B32: =SUM(B25:B31) -> 2131660 | C32: =SUM(C25:C31) -> 33.451431 | E32: TOTAL MATERIALES | F32: =SUM(F25:F31) -> 2512900 | G32: =SUM(G25:G31) -> 82.666432 | I32: TOTAL MATERIALES | J32: =SUM(J25:J31) -> 9335345 | K32: =SUM(K25:K31) -> 209.51242
A34: V2AG-14C086 | E34: V2AJ-21E063
A35: Elemento | B35: Precio | C35: PESO (KG) | E35: Elemento | F35: Precio | G35: PESO (KG)
A36: MR 0.55kW @ 85 RPM – RF37DRS71M4 | B36: =INSUMOS!B437 -> 1430000 | C36: =INSUMOS!E437 -> 36 | E36: MR 1,1kW @ 63RPM SK5721IEC90SK90S4 | F36: =INSUMOS!B526 -> 1400000 | G36: =INSUMOS!E527 -> 29
A37: Pletina 210 * 1/4" | B37: =INSUMOS!B112 -> 96000 | C37: =INSUMOS!E112 -> 2.1982747 | E37: Pletina 210 * 1/4" | F37: =INSUMOS!B112 -> 96000 | G37: =INSUMOS!E112 -> 2.1982747
A38: EJE EJDA145C | B38: =EJXA!D26 -> 152800 | C38: =EJXA!E26 -> 9.0118717 | E38: EJE EJDA210E | F38: =EJXA!D60 -> 400400 | G38: =EJXA!E60 -> 33.412291
A39: ACOPLE AD-025-032 | B39: =AD!D18 -> 232800 | C39: =AD!E18 -> 3.182123 | E39: ACOPLE AD-035-050 | F39: =AD!D25 -> 358200 | G39: =AD!E39 -> 7.1597767
A40: PROPELA P2-HCM | B40: =P!D38 -> 563465 | C40: =P!E38 -> 6.4665922 | E40: PROPELA P2-KEM | F40: =P!D148 -> 859150 | G40: =P!E148 -> 29.369833
A41: PLACAS | B41: =INSUMOS!B537 -> 50000 | E41: PLACAS | F41: =INSUMOS!B537 -> 50000
A42: TORNILLOS AG PEQUEÑO | B42: =INSUMOS!B534 -> 50000 | C42: =INSUMOS!E534 -> 3 | E42: TORNILLOS AG MEDIANO | F42: =INSUMOS!B535 -> 80000 | G42: =INSUMOS!E535 -> 5
A43: TOTAL | B43: =SUM(B36:B42) -> 2575065 | C43: =SUM(C36:C42) -> 59.858862 | E43: TOTAL MATERIALES | F43: =SUM(F36:F42) -> 3243750 | G43: =SUM(G36:G42) -> 106.14018

Sheet V3
A1: V3AB-06B293 | E1: V3AF-13D129 | I1: V3AJ-20F159
A2: Elemento | B2: Precio | C2: PESO (KG) | E2: Elemento | F2: Precio | G2: PESO (KG) | I2: Elemento | J2: Precio | K2: PESO (KG)
A3: MR 0.37kW @ 293 RPM RF07DRS71S4 | B3: =INSUMOS!B424 -> 1155000 | C3: =INSUMOS!E424 -> 9 | E3: MR 0.75kW @ 129 RPM RF27DRS80S4 | F3: =INSUMOS!B432 -> 1492202.8 | G3: =INSUMOS!E432 -> 21 | I3: MR 1,5kW @ 159 RPM SK12-90L/4 | J3: =INSUMOS!B518 -> 1259874 | K3: =INSUMOS!E518 -> 43
A4: Pletina 210 * 1/4" | B4: =INSUMOS!B112 -> 96000 | C4: =INSUMOS!E112 -> 2.1982747 | E4: Pletina 210 * 1/4" | F4: =INSUMOS!B112 -> 96000 | G4: =INSUMOS!E112 -> 2.1982747 | I4: Pletina 210 * 1/4" | J4: =INSUMOS!B112 -> 96000 | K4: =INSUMOS!E112 -> 2.1982747
A5: EJE EJDA059B | B5: =EJXA!D67 -> 83010 | C5: =EJXA!E67 -> 2.3468157 | E5: EJE EJDA135C | F5: =EJXA!D100 -> 146400 | G5: =EJXA!E100 -> 8.3903633 | I5: EJE EJDA206D | J5: =EJXA!D121 -> 256220 | K5: =EJXA!E121 -> 18.436425
A6: ACOPLE AD-020-025 | B6: =AD!D5 -> 197400 | C6: =AD!E5 -> 1.7899442 | E6: ACOPLE AD-020-032 | F6: =AD!D12 -> 232800 | G6: =AD!E12 -> 3.182123 | I6: ACOPLE AD-025-038 | J6: =AD!D32 -> 232800 | K6: =AD!E32 -> 3.182123
A7: PROPELA P3-BBM | B7: =P!D187 -> 436250 | C7: =P!E187 -> 2.2424581 | E7: PROPELA P3-GCM | F7: =P!D217 -> 573100 | G7: =P!E217 -> 7.1865922 | I7: PROPELA P3-KDC | J7: =P!D246 -> 790000 | K7: =P!E246 -> 14.3
A8: PLACAS | B8: =INSUMOS!B537 -> 50000 | E8: PLACAS | F8: =INSUMOS!B537 -> 50000 | I8: PLACAS | J8: =INSUMOS!B537 -> 50000
A9: TORNILLOS AG PEQUEÑO | B9: =INSUMOS!B534 -> 50000 | C9: =INSUMOS!E534 -> 3 | E9: TORNILLOS AG PEQUEÑO | F9: =INSUMOS!B534 -> 50000 | G9: =INSUMOS!E534 -> 3 | I9: TORNILLOS AG MEDIANO | J9: =INSUMOS!B535 -> 80000 | K9: =INSUMOS!E535 -> 5
A10: TOTAL MATERIALES | B10: =SUM(B3:B9) -> 2067660 | C10: =SUM(C3:C9) -> 20.577493 | E10: TOTAL MATERIALES | F10: =SUM(F3:F9) -> 2640502.8 | G10: =SUM(G3:G9) -> 44.957353 | I10: TOTAL MATERIALES | J10: =SUM(J3:J9) -> 2764894 | K10: =SUM(K3:K9) -> 86.116823
A12: V3AC-09A189 | E12: V3AH-16G118 | I12: V3AK-26G118
A13: Elemento | B13: Precio | C13: PESO (KG) | E13: Elemento | F13: Precio | G13: PESO (KG) | I13: Elemento | J13: Precio | K13: PESO (KG)
A14: MR 0.25kW @ 189 RPM RF07DRS71S4 | B14: =INSUMOS!B424 -> 1155000 | C14: =INSUMOS!E424 -> 9 | E14: MR 2,2kW @ 118 RPM RF47DRS90L4 | F14: =INSUMOS!B448 -> 1893000 | G14: =INSUMOS!E445 -> 43 | I14: MR 2,2kW @ 118 RPM RF47DRS90L4 | J14: =INSUMOS!B448 -> 1893000 | K14: =INSUMOS!E446 -> 43
A15: Pletina 210 * 1/4" | B15: =INSUMOS!B112 -> 96000 | C15: =INSUMOS!E112 -> 2.1982747 | E15: Pletina 210 * 1/4" | F15: =INSUMOS!B112 -> 96000 | G15: =INSUMOS!E112 -> 2.1982747 | I15: Pletina 210 * 1/4" | J15: =INSUMOS!B112 -> 96000 | K15: =INSUMOS!E112 -> 2.1982747
A16: EJE EJDA086B | B16: =EJXA!D74 -> 93540 | C16: =EJXA!E74 -> 3.4207822 | E16: EJE EJDA162E | F16: =EJXA!D107 -> 326480 | G16: =EJXA!E107 -> 25.775196 | I16: EJE EJDA260E | J16: =EJXA!D140 -> 477400 | K16: =EJXA!E140 -> 41.367599
A17: ACOPLE AD-020-025 | B17: =AD!D5 -> 197400 | C17: =AD!E5 -> 1.7899442 | E17: ACOPLE AD-030-050 | F17: =AD!D46 -> 358200 | G17: =AD!E46 -> 7.1597767 | I17: ACOPLE AD-030-050 | J17: =AD!D46 -> 358200 | K17: =AD!E46 -> 7.1597767
A18: PROPELA P3-CBM | B18: =P!D197 -> 451250 | C18: =P!E197 -> 2.9424581 | E18: PROPELA P3-IEM | F18: =P!D227 -> 759150 | G18: =P!E227 -> 10.869833 | I18: PROPELA P3-LEC | J18: =P!D256 -> 1220000 | K18: =P!E256 -> 26.5
A19: PLACAS | B19: =INSUMOS!B537 -> 50000 | E19: PLACAS | F19: =INSUMOS!B537 -> 50000 | I19: PLACAS | J19: =INSUMOS!B537 -> 50000
A20: TORNILLOS AG PEQUEÑO | B20: =INSUMOS!B534 -> 50000 | C20: =INSUMOS!E534 -> 3 | E20: TORNILLOS AG MEDIANO | F20: =INSUMOS!B535 -> 80000 | G20: =INSUMOS!E535 -> 5 | I20: TORNILLOS AG GRANDE | J20: =INSUMOS!B536 -> 120000 | K20: =INSUMOS!E536 -> 9
A21: TOTAL MATERIALES | B21: =SUM(B14:B20) -> 2093190 | C21: =SUM(C14:C20) -> 22.351459 | E21: TOTAL MATERIALES | F21: =SUM(F14:F20) -> 3562830 | G21: =SUM(G14:G20) -> 94.00308 | I21: TOTAL MATERIALES | J21: =SUM(J14:J20) -> 4214600 | K21: =SUM(K14:K20) -> 129.22565
A23: V3AE-11B120 | E23: V3AI-18F089 | I23: V3AL-26H095
A24: Elemento | B24: Precio | C24: PESO (KG) | E24: Elemento | F24: Precio | G24: PESO (KG) | I24: Elemento | J24: Precio | K24: PESO (KG)
A25: MR 0.37kW @ 120 RPM RF07DRS71S4 | B25: =INSUMOS!B424 -> 1155000 | C25: =INSUMOS!E424 -> 9 | E25: MR 1,5kW @ 89 RPM RF47DRS90M4 | F25: =INSUMOS!B446 -> 1993000 | G25: =INSUMOS!E448 -> 43 | I25: MR 3kW @ 95 RPM RF67DRS100M4 | J25: =INSUMOS!B465 -> 2486000 | K25: =INSUMOS!E465 -> 73
A26: Pletina 210 * 1/4" | B26: =INSUMOS!B112 -> 96000 | C26: =INSUMOS!E112 -> 2.1982747 | E26: Pletina 210 * 1/4" | F26: =INSUMOS!B112 -> 96000 | G26: =INSUMOS!E112 -> 2.1982747 | I26: Pletina 250 * 1/4" | J26: =INSUMOS!B113 -> 100000 | K26: =INSUMOS!E113 -> 3.1154687
A27: EJE EJDA108B | B27: =EJXA!D93 -> 102120 | C27: =EJXA!E93 -> 4.295866 | E27: EJE EJDA184E | F27: =EJXA!D114 -> 360360 | G27: =EJXA!E114 -> 29.275531 | I27: EJE EJDA264E | J27: =EJXA!D147 -> 483560 | K27: =EJXA!E147 -> 42.004023
A28: ACOPLE AD-020-025 | B28: =AD!D5 -> 197400 | C28: =AD!E5 -> 1.7899442 | E28: ACOPLE AD-030-050 | F28: =AD!D46 -> 358200 | G28: =AD!E46 -> 7.1597767 | I28: ACOPLE AD-035-050 | J28: =AD!D39 -> 358200 | K28: =AD!E39 -> 7.1597767
A29: PROPELA P3-EBM | B29: =P!D207 -> 476250 | C29: =P!E207 -> 4.5424581 | E29: PROPELA P3-JEC | F29: =P!D236 -> 745000 | G29: =P!E236 -> 13.8 | I29: PROPELA P3-MEC | J29: =P!D266 -> 2070000 | K29: =P!E266 -> 32.5
A30: PLACAS | B30: =INSUMOS!B537 -> 50000 | E30: PLACAS | F30: =INSUMOS!B537 -> 50000 | I30: PLACAS | J30: =INSUMOS!B537 -> 50000
A31: TORNILLOS AG PEQUEÑO | B31: =INSUMOS!B534 -> 50000 | C31: =INSUMOS!E534 -> 3 | E31: TORNILLOS AG MEDIANO | F31: =INSUMOS!B535 -> 80000 | G31: =INSUMOS!E535 -> 5 | I31: TORNILLOS AG GRANDE | J31: =INSUMOS!B536 -> 120000 | K31: =INSUMOS!E536 -> 9
A32: TOTAL MATERIALES | B32: =SUM(B25:B31) -> 2126770 | C32: =SUM(C25:C31) -> 24.826543 | E32: TOTAL MATERIALES | F32: =SUM(F25:F31) -> 3682560 | G32: =SUM(G25:G31) -> 100.43358 | I32: TOTAL MATERIALES | J32: =SUM(J25:J31) -> 5667760 | K32: =SUM(K25:K31) -> 166.77927
A34: V3AC-06A163
A35: Elemento | B35: Precio | C35: PESO (KG)
A36: MR 0.25kW @ 163 RPM SK072 | B36: =INSUMOS!B524 -> 850000 | C36: =INSUMOS!E524 -> 9
A37: Pletina 170 * 1/4" | B37: =INSUMOS!B111 -> 90000 | C37: =INSUMOS!E111 -> 1.4405927
A38: EJE EJDA065B | B38: =EJXA!D5 -> 85350 | C38: =EJXA!E5 -> 2.5854749
A39: ACOPLE AD-020-025 | B39: =AD!D5 -> 197400 | C39: =AD!E5 -> 1.7899442
A40: PROPELA P3-CBM | B40: =P!D197 -> 451250 | C40: =P!E218 -> 0
A41: PLACAS | B41: =INSUMOS!B537 -> 50000
A42: TORNILLOS AG PEQUEÑO | B42: =INSUMOS!B534 -> 50000 | C42: =INSUMOS!E545 -> 0
A43: TOTAL MATERIALES | B43: =SUM(B36:B42) -> 1774000 | C43: =SUM(C36:C42) -> 14.816012

Sheet V4
A1: V4AE-09B107 | E1: V4AK-27G053
A2: Elemento | B2: Precio | C2: PESO (KG) | E2: Elemento | F2: Precio | G2: PESO (KG)
A3: MR 0.37 kW @ 107 RPM RF17DRS71S4 | B3: =INSUMOS!B426 -> 1200000 | C3: =INSUMOS!E426 -> 16 | E3: MR 2,2 kW @ 53 RPM RF77DRS90L4 | F3: =INSUMOS!B474 -> 3065000 | G3: =INSUMOS!E474 -> 115
A4: Pletina 210 * 1/4" | B4: =INSUMOS!B112 -> 96000 | C4: =INSUMOS!E112 -> 2.1982747 | E4: Pletina 300 * 1/4" | F4: =INSUMOS!B116 -> 110000 | G4: =INSUMOS!E116 -> 4.486275
A5: EJE EJDA090B | B5: =EJXA!D12 -> 95100 | C5: =EJXA!E12 -> 3.5798883 | E5: EJE EJBC270G | F5: =EJXC!D20 -> 1711923 | G5: =EJXC!E20 -> 35.44
A6: ACOPLE AD-020-025 | B6: =AD!D5 -> 197400 | C6: =AD!E5 -> 1.7899442 | E6: ACOPLE AB-3-40 | F6: =AB!D27 -> 546265 | G6: =AB!E27 -> 9.0468716
A7: PROPELA P4-EBM | B7: =P!D306 -> 526250 | C7: =P!E306 -> 5.6424581 | E7: PROPELA P4-LGC | F7: =P!D366 -> 1486000 | G7: =P!C366 -> TOTAL
A8: PLACAS | B8: =INSUMOS!B537 -> 50000 | E8: PLACAS | F8: =INSUMOS!B537 -> 50000
A9: TORNILLOS AG PEQUEÑO | B9: =INSUMOS!B534 -> 50000 | C9: =INSUMOS!E534 -> 3 | E9: TORNILLOS AG MEDIANO | F9: =INSUMOS!B535 -> 80000 | G9: =INSUMOS!E535 -> 5
A10: TOTAL MATERIALES | B10: =SUM(B3:B9) -> 2214750 | C10: =SUM(C3:C9) -> 32.210565 | E10: TOTAL MATERIALES | F10: =SUM(F3:F9) -> 7049188 | G10: =SUM(G3:G9) -> 168.97315
A12: V4AH-12E068 | E12: V4AL-27H043
A13: Elemento | B13: Precio | C13: PESO (KG) | E13: Elemento | F13: Precio | G13: PESO (KG)
A14: MR 1,1 kW @ 68 RPM SK1 SMI 63 | B14: =INSUMOS!B522 -> 1400000 | C14: =INSUMOS!E445 -> 43 | E14: MR 3 kW @ 43 RPM RF87DRS100M4 | F14: =INSUMOS!B482 -> 4102000 | G14: =INSUMOS!E482 -> 145
A15: Pletina 210 * 1/4" | B15: =INSUMOS!B112 -> 96000 | C15: =INSUMOS!E112 -> 2.1982747 | E15: Pletina 350 * 1/4" | F15: =INSUMOS!B117 -> 115000 | G15: =INSUMOS!E117 -> 6.1063187
A16: EJE EJDA125E | B16: =EJXA!D186 -> 269500 | C16: =EJXA!E154 -> 23.865922 | E16: EJE EJBC270I | F16: =EJXC!D13 -> 2618025 | G16: =EJXC!E13 -> 50.443
A17: ACOPLE AD-030-050 | B17: =AD!D46 -> 358200 | C17: =AD!E46 -> 7.1597767 | E17: ACOPLE AB-4-50 | F17: =AB!D13 -> 647320 | G17: =AB!E13 -> 15.909944
A18: PROPELA P4-IEC | B18: =P!D315 -> 690000 | C18: =P!E315 -> 12.7 | E18: PROPELA P4-MIC | F18: =P!D335 -> 2216000 | G18: =P!E335 -> 89.2
A19: PLACAS | B19: =INSUMOS!B537 -> 50000 | E19: PLACAS | F19: =INSUMOS!B537 -> 50000
A20: TORNILLOS AG PEQUEÑO | B20: =INSUMOS!B534 -> 50000 | C20: =INSUMOS!E534 -> 3 | E20: TORNILLOS AG GRANDE | F20: =INSUMOS!B536 -> 120000 | G20: =INSUMOS!E536 -> 9
A21: TOTAL MATERIALES | B21: =SUM(B14:B20) -> 2913700 | C21: =SUM(C14:C20) -> 91.923974 | E21: TOTAL MATERIALES | F21: =SUM(F14:F20) -> 9868345 | G21: =SUM(G14:G20) -> 315.65926
A23: V4AJ-21E065 | E23: V4AV-27H033
A24: Elemento | B24: Precio | C24: PESO (KG) | E24: Elemento | F24: Precio | G24: PESO (KG)
A25: MR 1,1 kW @ 65 RPM RF47DRS80M4 | B25: =INSUMOS!B445 -> 1882100 | C25: =INSUMOS!E445 -> 43 | E25: MR 3 kW @ 33 RPM RF87DRS100M4 | F25: =INSUMOS!B482 -> 4102000 | G25: =INSUMOS!E482 -> 145
A26: Pletina 210 * 1/4" | B26: =INSUMOS!B112 -> 96000 | C26: =INSUMOS!E112 -> 2.1982747 | E26: Pletina 350 * 1/4" | F26: =INSUMOS!B117 -> 115000 | G26: =INSUMOS!E117 -> 6.1063187
A27: EJE EJDA216E | B27: =EJXA!D161 -> 409640 | C27: =EJXA!E161 -> 34.366928 | E27: EJE EJBC270I | F27: =EJXC!D13 -> 2618025 | G27: =EJXC!E13 -> 50.443
A28: ACOPLE AD-030-050 | B28: =AD!D46 -> 358200 | C28: =AD!E46 -> 7.1597767 | E28: ACOPLE AB-4-50 | F28: =AB!D13 -> 647320 | G28: =AB!E13 -> 15.909944
A29: PROPELA P4-KEC | B29: =P!D325 -> 820000 | C29: =P!E325 -> 39.4 | E29: PROPELA P4-RIC | F29: =P!D346 -> 2670000 | G29: =P!E346 -> 108.4
A30: PLACAS | B30: =INSUMOS!B537 -> 50000 | E30: PLACAS | F30: =INSUMOS!B537 -> 50000
A31: TORNILLOS AG PEQUEÑO | B31: =INSUMOS!B534 -> 50000 | C31: =INSUMOS!E534 -> 3 | E31: TORNILLOS AG GRANDE | F31: =INSUMOS!B536 -> 120000 | G31: =INSUMOS!E536 -> 9
A32: TOTAL MATERIALES | B32: =SUM(B25:B31) -> 3665940 | C32: =SUM(C25:C31) -> 129.12498 | E32: TOTAL MATERIALES | F32: =SUM(F25:F31) -> 10322345 | G32: =SUM(G25:G31) -> 334.85926

Sheet OTROS AG
B2: VR23B-016/020
B3: Elemento | C3: Precio | D3: PESO (KG)
B4: MR 0,37 kW @ 325 RPM SF37DRS71S4 | C4: =INSUMOS!B531 -> 950000 | D4: =INSUMOS!E531 -> 25
B5: Pletina 210 * 1/4" | C5: =INSUMOS!B112 -> 96000 | D5: =INSUMOS!E112 -> 2.1982747
B6: EJE EJDA125B | C6: =EJXA!D174 -> 108750 | D6: =EJXA!E174 -> 4.9720671
B7: ACOPLE AD-020-025 | C7: =AD!D5 -> 197400 | D7: =AD!E5 -> 1.7899442
B8: PROPELA P2-ABM | C8: =P!B58 -> 0 | D8: =P!E58 -> 2.2424581
B9: PROPELA P3-BBM | C9: =P!B187 -> 0 | D9: =P!E187 -> 2.2424581
B10: PLACAS | C10: =INSUMOS!B537 -> 50000
B11: TORNILLOS AG PEQUEÑO | C11: =INSUMOS!B534 -> 50000 | D11: =INSUMOS!I535 -> 0
B12: TOTAL MATERIALES | C12: =SUM(C4:C11) -> 1452150 | D12: =SUM(D4:D11) -> 38.445202
B15: V3AC2AB06A163
B16: Elemento | C16: Precio | D16: PESO (KG)
B17: MR 0.25kW @ 163 RPM SK072 | C17: =INSUMOS!B524 -> 850000 | D17: =INSUMOS!E424 -> 9
B18: Pletina 170 * 1/4" | C18: =INSUMOS!B111 -> 90000 | D18: =INSUMOS!E111 -> 1.4405927
B19: EJE EJDA065B | C19: =EJXA!D5 -> 85350 | D19: =EJXA!E5 -> 2.5854749
B20: ACOPLE AD-020-025 | C20: =AD!D5 -> 197400 | D20: =EJXA!E5 -> 2.5854749
B21: PROPELA P2-BBM | C21: =P!D8 -> 391250 | D21: =P!E8 -> 2.3124581
B22: PROPELA P3-CBM | C22: =P!D197 -> 451250 | D22: =P!E197 -> 2.9424581
B23: PLACAS | C23: =INSUMOS!B537 -> 50000
B24: TORNILLOS AG PEQUEÑO | C24: =INSUMOS!B534 -> 50000 | D24: =INSUMOS!E534 -> 3
B25: TOTAL MATERIALES | C25: =SUM(C17:C24) -> 2165250 | D25: =SUM(D17:D24) -> 23.866459
B28: V3AC-06A163
B29: Elemento | C29: Precio | D29: PESO (KG)
B30: MR 0.25kW @ 163 RPM SK072 | C30: =INSUMOS!B524 -> 850000 | D30: =INSUMOS!E524 -> 9
B31: Pletina 170 * 1/4" | C31: =INSUMOS!B111 -> 90000 | D31: =INSUMOS!E111 -> 1.4405927
B32: EJE EJDA065B | C32: =EJXA!D5 -> 85350 | D32: =EJXA!E5 -> 2.5854749
B33: ACOPLE AD-020-025 | C33: =AD!D5 -> 197400 | D33: =EJXA!E5 -> 2.5854749
B34: PROPELA P3-CBM | C34: =P!D197 -> 451250 | D34: =P!E197 -> 2.9424581
B35: PLACAS | C35: =INSUMOS!B537 -> 50000
B36: TORNILLOS AG PEQUEÑO | C36: =INSUMOS!B534 -> 50000 | D36: =INSUMOS!E534 -> 3
B37: TOTAL MATERIALES | C37: =SUM(C30:C36) -> 1774000 | D37: =SUM(D30:D36) -> 21.554001
B39: V6AE-09A085
B40: Elemento | C40: Precio | D40: PESO (KG)
B41: MR 0.25kW @ 85 RPM SK1SMI31 | C41: =INSUMOS!B520 -> 800000 | D41: =INSUMOS!E520 -> 12
B42: Pletina 170 * 1/4" | C42: =INSUMOS!B111 -> 90000 | D42: =INSUMOS!E111 -> 1.4405927
B43: EJE EJDA090B | C43: =EJXA!D12 -> 95100 | D43: =EJXA!E12 -> 3.5798883
B44: ACOPLE AD-020-025 | C44: =AD!D5 -> 197400 | D44: =AD!E5 -> 1.7899442
B45: PROPELA P0-EBM | C45: =P!D434 -> 576250 | D45: =P!E208 -> 0
B46: PLACAS | C46: =INSUMOS!B537 -> 50000
...

Sheet EJXA
A1: EJDA065B
A2: Elemento | B2: Precio Unit. | C2: Cant. | D2: Parcial | E2: Peso (kg)
A3: Barra 1 " * 650 mm 304SS | B3: =INSUMOS!B2 -> 39000 | C3: 0.65 | D3: =C3*B3 -> 25350 | E3: =C3*INSUMOS!E2 -> 2.5854749
A4: Mecanizado eje macizo 1" | B4: =INSUMOS!B259 -> 60000 | C4: 1 | D4: =C4*B4 -> 60000 | E4: -
C5: TOTAL | D5: =SUM(D3:D4) -> 85350 | E5: =SUM(E3:E4) -> 2.5854749
A8: EJDA090B
A9: Elemento | B9: Precio | E9: Peso (kg)
A10: Barra 1 " * 900 mm 304SS | B10: =INSUMOS!B2 -> 39000 | C10: 0.9 | D10: =C10*B10 -> 35100 | E10: =C10*INSUMOS!E2 -> 3.5798883
A11: Mecanizado eje macizo 1" | B11: =INSUMOS!B259 -> 60000 | C11: 1 | D11: =C11*B11 -> 60000 | E11: -
C12: TOTAL | D12: =SUM(D10:D11) -> 95100 | E12: =SUM(E10:E11) -> 3.5798883
A15: EJDA109C
A16: Elemento | B16: Precio | C16: Cant. | D16: Parcial | E16: Peso (kg)
A17: Barra 1 1/4" * 1090 mm 304SS | B17: =INSUMOS!B3 -> 64000 | C17: 1.09 | D17: =C17*B17 -> 69760 | E17: =C17*INSUMOS!E3 -> 6.7744415
A18: Mecanizado eje macizo 1 1/4" | B18: =INSUMOS!B260 -> 60000 | C18: 1 | D18: =C18*B18 -> 60000 | E18: -
C19: TOTAL | D19: =SUM(D17:D18) -> 129760 | E19: =SUM(E17:E18) -> 6.7744415
A22: EJDA145C
A23: Elemento | B23: Precio | C23: Cant. | D23: Parcial | E23: Peso (kg)
A24: Barra 1 1/4" * 1450 mm 304SS | B24: =INSUMOS!B3 -> 64000 | C24: 1.45 | D24: =C24*B24 -> 92800 | E24: =C24*INSUMOS!E3 -> 9.0118717
A25: Mecanizado eje macizo 1 1/4" | B25: =INSUMOS!B260 -> 60000 | C25: 1 | D25: =C25*B25 -> 60000 | E25: -
C26: TOTAL | D26: =SUM(D24:D25) -> 152800 | E26: =SUM(E24:E25) -> 9.0118717
A29: EJDA160E
A30: Elemento | B30: Precio | C30: Cant. | D30: Parcial | E30: Peso (kg)
A31: Barra 2" * 1600 mm 304SS | B31: =INSUMOS!B5 -> 154000 | C31: 1.6 | D31: =C31*B31 -> 246400 | E31: =C31*INSUMOS!E5 -> 25.456984
A32: Mecanizado eje macizo 1 1/4" | B32: =INSUMOS!B262 -> 77000 | C32: 1 | D32: =C32*B32 -> 77000 | E32: -
C33: TOTAL | D33: =SUM(D31:D32) -> 323400 | E33: =SUM(E31:E32) -> 25.456984
A35: EJDA106DS
A36: Elemento | B36: Precio | C36: Cant. | D36: Parcial | E36: Peso (kg)
A37: Barra 1 1/2 " * 1060 mm 316SS | B37: =INSUMOS!B15 -> 140000 | C37: 1.06 | D37: =C37*B37 -> 148400 | E37: =C37*INSUMOS!E4 -> 9.4867041
A38: Mecanizado eje macizo 1 1/2" | B38: =INSUMOS!B261 -> 77000 | C38: 1 | D38: =C38*B38 -> 77000 | E38: -
C39: TOTAL | D39: =SUM(D37:D38) -> 225400 | E39: =SUM(E37:E38) -> 9.4867041
A42: EJDA180E
A43: Elemento | B43: Precio | C43: Cant. | D43: Parcial | E43: Peso (kg)
A44: Barra 2 " * 1800 mm 304SS | B44: =INSUMOS!B5 -> 154000 | C44: 1.8 | D44: =C44*B44 -> 277200 | E44: =C44*INSUMOS!E5 -> 28.639107
A45: Mecanizado eje macizo 2" | B45: =INSUMOS!B262 -> 77000 | C45: 1 | D45: =C45*B45 -> 77000 | E45: -
C46: TOTAL | D46: =SUM(D44:D45) -> 354200 | E46: =SUM(E44:E45) -> 28.639107
A49: EJDA200D
A50: Elemento | B50: Precio | C50: Cant. | D50: Parcial | E50: Peso (kg)
A51: Barra 1 1/2 " * 2000 mm 304SS | B51: =INSUMOS!B4 -> 87000 | C51: 2 | D51: =C51*B51 -> 174000 | E51: =C51*INSUMOS!E4 -> 17.899442
A52: Mecanizado eje macizo 1 1/2" | B52: =INSUMOS!B261 -> 77000 | C52: 1 | D52: =C52*B52 -> 77000 | E52: -
C53: TOTAL | D53: =SUM(D51:D52) -> 251000 | E53: =SUM(E51:E52) -> 17.899442
...

Sheet EJXC
A1: EJBC240G
A2: Elemento | B2: Precio Unit | C2: Cant. | D2: Parcial | E2: Peso (kg)
A3: Brida ciega de 3" 304SS | B3: =INSUMOS!B72 -> 98250 | C3: 1 | D3: =C3*B3 -> 98250 | E3: =INSUMOS!E72 -> 4.93
A4: Tubo de 3" SCH 40 304SS 2400 mm | B4: =INSUMOS!B48 -> 751564 | C4: 0.75 | D4: =C4*B4 -> 563673 | E4: =2.4*INSUMOS!E48 -> 27.12
A5: Maquinado de eje tubular de 3" | B5: =INSUMOS!B278 -> 1050000 | C5: 1 | D5: =C5*B5 -> 1050000 | E5: -
C6: TOTAL | D6: =SUM(D3:D5) -> 1711923 | E6: =SUM(E3:E5) -> 32.05
A8: EJBC270I
A9: Elemento | B9: Precio | C9: Cant. | D9: Parcial | E9: Peso (kg)
A10: Brida ciega de 4" 304SS | B10: =INSUMOS!B73 -> 148500 | C10: 1 | D10: =C10*B10 -> 148500 | E10: =INSUMOS!E73 -> 7
A11: Tubo de 4" SCH 40 304SS 2700 mm | B11: =INSUMOS!B49 -> 1052700 | C11: 0.75 | D11: =C11*B11 -> 789525 | E11: =2.7*INSUMOS!E49 -> 43.443
A12: Maquinado de eje tubular de 4" | B12: =INSUMOS!B279 -> 1680000 | C12: 1 | D12: =C12*B12 -> 1680000 | E12: -
C13: TOTAL | D13: =SUM(D10:D12) -> 2618025 | E13: =SUM(E10:E12) -> 50.443
A15: EJBC270G
A16: Elemento | B16: Precio | C16: Cant. | D16: Parcial | E16: Peso (kg)
A17: Brida ciega de 3" 304SS | B17: =INSUMOS!B72 -> 98250 | C17: 1 | D17: =C17*B17 -> 98250 | E17: =INSUMOS!E72 -> 4.93
A18: Tubo de 3" SCH 40 304SS 2700 mm | B18: =INSUMOS!B48 -> 751564 | C18: 0.75 | D18: =C18*B18 -> 563673 | E18: =2.7*INSUMOS!E48 -> 30.51
A19: Maquinado de eje tubular de 3" | B19: =INSUMOS!B278 -> 1050000 | C19: 1 | D19: =C19*B19 -> 1050000 | E19: -
C20: TOTAL | D20: =SUM(D17:D19) -> 1711923 | E20: =SUM(E17:E19) -> 35.44
A22: EJBC740JR
A23: Elemento | B23: Precio | C23: Cant. | D23: Parcial | E23: Peso (kg)
A24: Brida ciega de 6" A36 | B24: =INSUMOS!B103 -> 62500 | C24: 3 | D24: =C24*B24 -> 187500 | E24: =INSUMOS!E103 -> 11.3
A25: Tubo de 6" SCH 40 A36 7400 mm | B25: =INSUMOS!B65 -> 448340 | C25: 1.5 | D25: =C25*B25 -> 672510 | E25: =7.4*INSUMOS!E65 -> 208.68
A26: Maquinado de eje tubular de 6" | B26: =INSUMOS!B281 -> 2300000 | C26: 1 | D26: =C26*B26 -> 2300000 | E26: -
D27: =SUM(D24:D26) -> 3160010 | E27: =SUM(E24:E26) -> 219.98
A29: EJBC200G
A30: Elemento | B30: Precio | C30: Cant. | D30: Parcial | E30: Peso (kg)
A31: Brida ciega de 3" 304SS | B31: =INSUMOS!B72 -> 98250 | C31: 1 | D31: =C31*B31 -> 98250 | E31: =INSUMOS!E72 -> 4.93
A32: Tubo de 3" SCH 40 304SS 2000 mm | B32: =INSUMOS!B48 -> 751564 | C32: 0.5 | D32: =C32*B32 -> 375782 | E32: =1.8*INSUMOS!E48 -> 20.34
A33: Maquinado de eje tubular de 3" | B33: =INSUMOS!B278 -> 1050000 | C33: 1 | D33: =C33*B33 -> 1050000 | E33: -
D34: =SUM(D31:D33) -> 1524032 | E34: =SUM(E31:E33) -> 25.27
A37: EJBC200F
A38: Elemento | B38: Precio | C38: Cant. | D38: Parcial | E38: Peso (kg)
A39: Brida ciega de 2 1/2" 304SS | B39: =INSUMOS!B79 -> 82000 | C39: 1 | D39: =C39*B39 -> 82000 | E39: =INSUMOS!E79 -> 3.28
A40: Tubo de 2 1/2" SCH 40 304SS 2000 mm | B40: =INSUMOS!B47 -> 638000 | C40: 0.5 | D40: =C40*B40 -> 319000 | E40: =2*INSUMOS!E47 -> 17.26
A41: Maquinado de eje tubular de 2 1/2" | B41: =INSUMOS!B277 -> 600000 | C41: 1 | D41: =C41*B41 -> 600000
D42: =SUM(D39:D41) -> 1001000 | E42: =SUM(E39:E41) -> 20.54
A44: EJBC420I
A45: Elemento | B45: Precio | C45: Cant. | D45: Parcial | E45: Peso (kg)
A46: Brida ciega de 4" 304SS | B46: =INSUMOS!B73 -> 148500 | C46: 1 | D46: =C46*B46 -> 148500 | E46: =INSUMOS!E73 -> 7
A47: Tubo de 4" SCH 40 304SS 4200 mm | B47: =INSUMOS!B49 -> 1052700 | C47: 1 | D47: =C47*B47 -> 1052700 | E47: =INSUMOS!E49*4.2 -> 67.578
...

Sheet AB
A1: AB-4-60
A2: Elemento | B2: Precio | C2: Cant. | D2: Parcial | E2: Peso (kg)
A3: Brida ciega de 4" 304SS | B3: =INSUMOS!B73 -> 148500 | C3: 1 | D3: =C3*B3 -> 148500 | E3: =INSUMOS!E73 -> 7
A4: Barra 4 " * 160 mm 304SS | B4: =INSUMOS!B8 -> 563000 | C4: 0.16 | D4: =C4*B4 -> 90080 | E4: =0.16*INSUMOS!E8 -> 10.182793
A5: Mecanizado acople bridado 4" | B5: =INSUMOS!B271 -> 420000 | C5: 1 | D5: =C5*B5 -> 420000 | E5: -
C6: TOTAL | D6: =SUM(D3:D5) -> 658580 | E6: =SUM(E3:E5) -> 17.182793
A8: AB-4-50
A9: Elemento | B9: Precio | C9: Cant. | D9: Parcial | E9: Peso (kg)
A10: Brida ciega de 4" 304SS | B10: =INSUMOS!B73 -> 148500 | C10: 1 | D10: =C10*B10 -> 148500 | E10: =INSUMOS!E73 -> 7
A11: Barra 4 " * 140 mm 304SS | B11: =INSUMOS!B8 -> 563000 | C11: 0.14 | D11: =C11*B11 -> 78820 | E11: =0.14*INSUMOS!E8 -> 8.9099443
A12: Mecanizado acople bridado 4" | B12: =INSUMOS!B271 -> 420000 | C12: 1 | D12: =C12*B12 -> 420000 | E12: -
C13: TOTAL | D13: =SUM(D10:D12) -> 647320 | E13: =SUM(E10:E12) -> 15.909944
A15: AB-3-50
A16: Elemento | B16: Precio | C16: Cant. | D16: Parcial | E16: Peso (kg)
A17: Brida ciega de 3" 304SS | B17: =INSUMOS!B72 -> 98250 | C17: 1 | D17: =C17*B17 -> 98250 | E17: =INSUMOS!E72 -> 4.93
A18: Barra 3 " * 135 mm 304SS | B18: =INSUMOS!B7 -> 461000 | C18: 0.135 | D18: =C18*B18 -> 62235 | E18: =0.135*INSUMOS!E7 -> 4.8328493
A19: Mecanizado acople bridado 3" | B19: =INSUMOS!B270 -> 395000 | C19: 1 | D19: =C19*B19 -> 395000 | E19: -
C20: TOTAL | D20: =SUM(D17:D19) -> 555485 | E20: =SUM(E17:E19) -> 9.7628493
A22: AB-3-40
A23: Elemento | B23: Precio | C23: Cant. | D23: Parcial | E23: Peso (kg)
A24: Brida ciega de 3" 304SS | B24: =INSUMOS!B72 -> 98250 | C24: 1 | D24: =C24*B24 -> 98250 | E24: =INSUMOS!E72 -> 4.93
A25: Barra 3 " * 115 mm 304SS | B25: =INSUMOS!B7 -> 461000 | C25: 0.115 | D25: =C25*B25 -> 53015 | E25: =0.115*INSUMOS!E7 -> 4.1168716
A26: Mecanizado acople bridado 3" | B26: =INSUMOS!B270 -> 395000 | C26: 1 | D26: =C26*B26 -> 395000 | E26: -
C27: TOTAL | D27: =SUM(D24:D26) -> 546265 | E27: =SUM(E24:E26) -> 9.0468716
A29: AB-6-60-R
A30: Elemento | B30: Precio | C30: Cant. | D30: Parcial | E30: Peso (kg)
A31: Brida ciega de 6" A36 | B31: =INSUMOS!B103 -> 62500 | C31: 1 | D31: =C31*B31 -> 62500 | E31: =INSUMOS!E103 -> 11.3
A32: Barra 6 " * 170 mm A36 | B32: =INSUMOS!B9 -> 1267000 | C32: 0.17 | D32: =C32*B32 -> 215390 | E32: =INSUMOS!E30*0.17 -> 24.343241
A33: Mecanizado acople bridado 6" | B33: =INSUMOS!B272 -> 1305000 | C33: 1 | D33: =C33*B33 -> 1305000
C34: TOTAL | D34: =SUM(D31:D33) -> 1582890 | E34: =SUM(E31:E33) -> 35.643241
A36: AB-3-35
A37: Elemento | B37: Precio | C37: Cant. | D37: Parcial | E37: Peso (kg)
A38: Brida ciega de 3" 304SS | B38: =INSUMOS!B80 -> 78000 | C38: 1 | D38: =C38*B38 -> 78000 | E38: =INSUMOS!E72 -> 4.93
A39: Barra 3 " * 115 mm 304SS | B39: =INSUMOS!B7 -> 461000 | C39: 0.17 | D39: =C39*B39 -> 78370 | E39: =0.12*INSUMOS!E7 -> 4.295866
A40: Mecanizado acople bridado 3" | B40: =INSUMOS!B270 -> 395000 | C40: 1 | D40: =C40*B40 -> 395000 | E40: -
C41: TOTAL | D41: =SUM(D38:D40) -> 551370 | E41: =SUM(E38:E40) -> 9.225866
A43: AB-2.5-35
A44: Elemento | B44: Precio | C44: Cant. | D44: Parcial | E44: Peso (kg)
A45: Brida ciega de 2,5" 304SS | B45: =INSUMOS!B71 -> 80000 | C45: 1 | D45: =C45*B45 -> 80000 | E45: =INSUMOS!E79 -> 3.28
A46: Barra 3 " * 115 mm 304SS | B46: =INSUMOS!B7 -> 461000 | C46: 0.17 | D46: =C46*B46 -> 78370 | E46: =0.11*INSUMOS!E7 -> 3.9378772
...

Sheet AD
A1: AD-020-025
A2: Elemento | B2: Precio Unit | C2: Cant | D2: Parcial | E2: Peso (kg)
A3: Barra 1 1/2" * 200 mm 304SS | B3: =INSUMOS!B4 -> 87000 | C3: 0.2 | D3: =C3*B3 -> 17400 | E3: =0.2*INSUMOS!E4 -> 1.7899442
A4: Mecanizado Acople Directo 1 " | B4: =INSUMOS!B252 -> 180000 | C4: 1 | D4: =C4*B4 -> 180000 | E4: -
C5: TOTAL | D5: =SUM(D3:D4) -> 197400 | E5: =SUM(E3:E4) -> 1.7899442
A8: AD-020-032
A9: Elemento | B9: Precio Unit | C9: Cant | D9: Parcial | E9: Peso (kg)
A10: Barra 2" * 200 mm 304SS | B10: =INSUMOS!B5 -> 154000 | C10: 0.2 | D10: =C10*B10 -> 30800 | E10: =0.2*INSUMOS!E5 -> 3.182123
A11: Mecanizado Acople Directo 2" | B11: =INSUMOS!B255 -> 202000 | C11: 1 | D11: =C11*B11 -> 202000 | E11: -
C12: TOTAL | D12: =SUM(D10:D11) -> 232800 | E12: =SUM(E10:E11) -> 3.182123
A14: AD-025-032
A15: Elemento | B15: Precio Unit | C15: Cant | D15: Parcial | E15: Peso (kg)
A16: Barra 2" * 200 mm 304SS | B16: =INSUMOS!B5 -> 154000 | C16: 0.2 | D16: =C16*B16 -> 30800 | E16: =0.2*INSUMOS!E5 -> 3.182123
A17: Mecanizado Acople Directo 2" | B17: =INSUMOS!B255 -> 202000 | C17: 1 | D17: =C17*B17 -> 202000 | E17: -
C18: TOTAL | D18: =SUM(D16:D17) -> 232800 | E18: =SUM(E16:E17) -> 3.182123
A21: AD-035-050
A22: Elemento | B22: Precio Unit | C22: Cant | D22: Parcial | E22: Peso (kg)
A23: Barra 3" * 200 mm 304SS | B23: =INSUMOS!B7 -> 461000 | C23: 0.2 | D23: =C23*B23 -> 92200 | E23: =0.2*INSUMOS!E7 -> 7.1597767
A24: Mecanizado Acople Directo 3" | B24: =INSUMOS!B258 -> 266000 | C24: 1 | D24: =C24*B24 -> 266000 | E24: -
C25: TOTAL | D25: =SUM(D23:D24) -> 358200 | E25: =SUM(E23:E24) -> 7.1597767
A28: AD-025-038
A29: Elemento | B29: Precio Unit | C29: Cant | D29: Parcial | E29: Peso (kg)
A30: Barra 2" * 200 mm 304SS | B30: =INSUMOS!B5 -> 154000 | C30: 0.2 | D30: =C30*B30 -> 30800 | E30: =0.2*INSUMOS!E5 -> 3.182123
A31: Mecanizado Acople Directo 2" | B31: =INSUMOS!B255 -> 202000 | C31: 1 | D31: =C31*B31 -> 202000 | E31: -
C32: TOTAL | D32: =SUM(D30:D31) -> 232800 | E32: =SUM(E30:E31) -> 3.182123
A35: AD-035-050
A36: Elemento | B36: Precio Unit | C36: Cant | D36: Parcial | E36: Peso (kg)
A37: Barra 3" * 200 mm 304SS | B37: =INSUMOS!B7 -> 461000 | C37: 0.2 | D37: =C37*B37 -> 92200 | E37: =0.2*INSUMOS!E7 -> 7.1597767
A38: Mecanizado Acople Directo 3 " | B38: =INSUMOS!B258 -> 266000 | C38: 1 | D38: =C38*B38 -> 266000 | E38: -
C39: TOTAL | D39: =SUM(D37:D38) -> 358200 | E39: =SUM(E37:E38) -> 7.1597767
A42: AD-030-050
A43: Elemento | B43: Precio Unit | C43: Cant | D43: Parcial | E43: Peso (kg)
A44: Barra 3" * 200 mm 304SS | B44: =INSUMOS!B7 -> 461000 | C44: 0.2 | D44: =C44*B44 -> 92200 | E44: =0.2*INSUMOS!E7 -> 7.1597767
A45: Mecanizado Acople Directo 3" | B45: =INSUMOS!B258 -> 266000 | C45: 1 | D45: =C45*B45 -> 266000 | E45: -
C46: TOTAL | D46: =SUM(D44:D45) -> 358200 | E46: =SUM(E44:E45) -> 7.1597767
A48: AD-020-038
A49: Elemento | B49: Precio Unit | C49: Cant | D49: Parcial | E49: Peso (kg)
A50: Barra 2" * 112 mm 304SS | B50: =INSUMOS!B5 -> 154000 | C50: 0.15 | D50: =C50*B50 -> 23100 | E50: =0.2*INSUMOS!E5 -> 3.182123
A51: Mecanizado Acople Directo 2" | B51: =INSUMOS!B255 -> 202000 | C51: 1 | D51: =C51*B51 -> 202000 | E51: -
C52: TOTAL | D52: =SUM(D50:D51) -> 225100 | E52: =SUM(E50:E51) -> 3.182123
...

Sheet P
A1: P2-BBM
A2: Elemento | B2: Precio Unit. | C2: Cant. | D2: Parcial | E2: Peso (kg)
A3: Material Propelas T200 | B3: =INSUMOS!B128 -> 120000 | C3: 1 | D3: =C3*B3 -> 120000 | E3: =INSUMOS!E128 -> 0.97
A4: Barra de 1 1/2" * 0,15 m 304SS | B4: =INSUMOS!B4 -> 87000 | C4: 0.15 | D4: =C4*B4 -> 13050 | E4: =0.15*INSUMOS!E4 -> 1.3424581
A5: Maquinado de manzana de 1 1/2" | B5: =INSUMOS!B296 -> 178200 | C5: 1 | D5: =C5*B5 -> 178200 | E5: -
A6: Mecanizado Propelas T200 | B6: =INSUMOS!B286 -> 50000 | C6: 1 | D6: =C6*B6 -> 50000
A7: SandBlasting T200 | B7: =INSUMOS!B300 -> 30000 | C7: 1 | D7: =C7*B7 -> 30000
C8: TOTAL | D8: =SUM(D3:D7) -> 391250 | E8: =SUM(E3:E7) -> 2.3124581
A11: P2-DBM
A12: Elemento | B12: Precio Unit. | C12: Cant. | D12: Parcial | E12: Peso (kg)
A13: Material Propelas T350 | B13: =INSUMOS!B130 -> 130000 | C13: 1 | D13: =C13*B13 -> 130000 | E13: =INSUMOS!E130 -> 2.91
A14: Barra de 1 1/2" * 0,15 m 304SS | B14: =INSUMOS!B4 -> 87000 | C14: 0.15 | D14: =C14*B14 -> 13050 | E14: =0.15*INSUMOS!E4 -> 1.3424581
A15: Maquinado de manzana de 1 1/2" | B15: =INSUMOS!B296 -> 178200 | C15: 1 | D15: =C15*B15 -> 178200 | E15: -
A16: Mecanizado Propelas T350 | B16: =INSUMOS!B288 -> 80000 | C16: 1 | D16: =C16*B16 -> 80000
A17: SandBlasting T350 | B17: =INSUMOS!B302 -> 40000 | C17: 1 | D17: =C17*B17 -> 40000
C18: TOTAL | D18: =SUM(D13:D17) -> 441250 | E18: =SUM(E13:E17) -> 4.2524581
A21: P2-DCM
A22: Elemento | B22: Precio Unit. | C22: Cant. | D22: Parcial | E22: Peso (kg)
A23: Material Propelas T350 | B23: =INSUMOS!B130 -> 130000 | C23: 1 | D23: =C23*B23 -> 130000 | E23: =INSUMOS!E130 -> 2.91
A24: Barra de 2" * 0,15 m 304SS | B24: =INSUMOS!B5 -> 154000 | C24: 0.15 | D24: =C24*B24 -> 23100 | E24: =0.15*INSUMOS!E5 -> 2.3865922
A25: Maquinado de manzana de 2" | B25: =INSUMOS!B297 -> 200000 | C25: 1 | D25: =C25*B25 -> 200000 | E25: -
A26: Mecanizado Propelas T350 | B26: =INSUMOS!B288 -> 80000 | C26: 1 | D26: =C26*B26 -> 80000
A27: SandBlasting T350 | B27: =INSUMOS!B302 -> 40000 | C27: 1 | D27: =C27*B27 -> 40000
C28: TOTAL | D28: =SUM(D23:D27) -> 473100 | E28: =SUM(E23:E27) -> 5.2965922
A31: P2-HCM
A32: Elemento | B32: Precio Unit. | C32: Cant. | D32: Parcial | E32: Peso (kg)
A33: Material Propelas T550 | B33: =INSUMOS!B132 -> 170000 | C33: 1 | D33: =C33*B33 -> 170000 | E33: =INSUMOS!E132 -> 4.08
A34: Barra de 2" * 0,15 m 304SS | B34: =0.15*INSUMOS!B5 -> 23100 | C34: 0.15 | D34: =C34*B34 -> 3465 | E34: =0.15*INSUMOS!E5 -> 2.3865922
A35: Maquinado de manzana de 2" | B35: =INSUMOS!B297 -> 200000 | C35: 1 | D35: =C35*B35 -> 200000 | E35: -
A36: Mecanizado Propelas T550 | B36: =INSUMOS!B290 -> 130000 | C36: 1 | D36: =C36*B36 -> 130000
A37: SandBlasting T550 | B37: =INSUMOS!B304 -> 60000 | C37: 1 | D37: =C37*B37 -> 60000
C38: TOTAL | D38: =SUM(D33:D37) -> 563465 | E38: =SUM(E33:E37) -> 6.4665922
A41: P2-BCM
A42: Elemento | B42: Precio Unit. | C42: Cant. | D42: Parcial | E42: Peso (kg)
A43: Material Propelas T200 | B43: =INSUMOS!B128 -> 120000 | C43: 1 | D43: =C43*B43 -> 120000 | E43: =INSUMOS!E128 -> 0.97
A44: Barra de 2" * 0,15 m 304SS | B44: =INSUMOS!B5 -> 154000 | C44: 0.15 | D44: =C44*B44 -> 23100 | E44: =0.15*INSUMOS!E5 -> 2.3865922
A45: Maquinado de manzana de 2" | B45: =INSUMOS!B297 -> 200000 | C45: 1 | D45: =C45*B45 -> 200000 | E45: -
A46: Mecanizado Propelas T200 | B46: =INSUMOS!B286 -> 50000 | C46: 1 | D46: =C46*B46 -> 50000
A47: SandBlasting T200 | B47: =INSUMOS!B300 -> 30000 | C47: 1 | D47: =C47*B47 -> 30000
C48: TOTAL | D48: =SUM(D43:D47) -> 423100 | E48: =SUM(E43:E47) -> 3.3565922
...

Sheet INSUMOS
A1: BARRAS MACIZAS 304SS | B1: VALOR / m | C1: ULTIMA COTIZACION | D1: EMPRESA | E1: PESO POR METRO (KG)
A2: 1 " | B2: 39000 | C2: 42426 | D2: CORTEACEROS | E2: =PI()*0.0254^2/4*7850 -> 3.9776537
A3: 1 1/4" | B3: 64000 | C3: 42426 | D3: CORTEACEROS | E3: =PI()*(1.25*0.0254)^2/4*7850 -> 6.2150839
A4: 1 1/2" | B4: 87000 | C4: 42426 | D4: CORTEACEROS | E4: =PI()*(1.5*0.0254)^2/4*7850 -> 8.9497208
A5: 2" | B5: 154000 | C5: 42426 | D5: CORTEACEROS | E5: =PI()*(2*0.0254)^2/4*7850 -> 15.910615
A6: 2 1/2" | B6: 225000 | C6: 42426 | D6: CORTEACEROS | E6: =PI()*(2.5*0.0254)^2/4*7850 -> 24.860336
A7: 3" | B7: 461000 | C7: 42444 | D7: IMPORINOX | E7: =PI()*(3*0.0254)^2/4*7850 -> 35.798883
A8: 4" | B8: 563000 | C8: 42429 | D8: CORTEACEROS | E8: =PI()*(4*0.0254)^2/4*7850 -> 63.642459
A9: 6" | B9: 1267000 | C9: 42474 | D9: CORTEACEROS | E9: =PI()*(6*0.0254)^2/4*7850 -> 143.19553
A10: 8" | B10: 2765000 | C10: 42479 | D10: CORTEACEROS | E10: =PI()*(8*0.0254)^2/4*7850 -> 254.56984
A11: 10" | B11: 4000000 | C11: 42697 | D11: IMPORINOX | E11: =PI()*(10*0.0254)^2/4*7850 -> 397.76537
A12: BARRAS MACIZAS 316SS | B12: VALOR / m | C12: ULTIMA COTIZACION | D12: EMPRESA | E12: PESO POR METRO (KG)
A13: 1" | B13: 80000 | C13: SUPUESTO | D13: IMPORINOX | E13: =E2 -> 3.9776537
A14: 1 1/4" | B14: 120000 | C14: SUPUESTO | D14: IMPORINOX | E14: =E3 -> 6.2150839
A15: 1 1/2" | B15: 140000 | C15: 42460 | D15: IMPORINOX | E15: =E4 -> 8.9497208
A16: 2" | B16: 240000 | C16: 42444 | D16: IMPORINOX | E16: =E5 -> 15.910615
A17: 2 1/4" | B17: 265000 | C17: 42444 | D17: IMPORINOX | E17: =PI()*(2.25*0.0254)^2/4*7850 -> 20.136872
A18: 2 1/2" | B18: 322000 | C18: 42444 | D18: IMPORINOX | E18: =E6 -> 24.860336
A19: 3" | B19: 461000 | C19: 42444 | D19: IMPORINOX | E19: =E7 -> 35.798883
A20: 3 1/2" | B20: 625000 | C20: 42444 | D20: IMPORINOX | E20: =PI()*(3.5*0.0254)^2/4*7850 -> 48.726258
A21: 4" | B21: 720000 | C21: 42521 | D21: IMPORINOX | E21: =PI()*(4*0.0254)^2/4*7850 -> 63.642459
A22: 6" | B22: =B21*POWER(6/4,2)*1.2 -> 1944000 | C22: 42528 | D22: Estimado extrapolacion | E22: 143.2
A23: 8" | B23: =1.3*B10 -> 3594500 | C23: 42521 | D23: IMPORINOX | E23: =PI()*(8*0.0254)^2/4*7850 -> 254.56984
A24: 10" | B24: 6500000 | C24: ESTIMADO | D24: IMPORINOX | E24: =PI()*(10*0.0254)^2/4*7850 -> 397.76537
A25: BARRAS MACIZAS 4140 | B25: VALOR / m | C25: ULTIMA COTIZACION | D25: EMPRESA | E25: PESO POR METRO (KG)
A26: 1 1/4" | B26: 35500 | C26: 42579 | D26: ACEROSCOL | E26: =PI()*(1.25*0.0254)^2/4*7850 -> 6.2150839
A27: 1 3/8" | B27: 42500 | C27: 42579 | D27: ACEROSCOL | E27: =PI()*(1.375*0.0254)^2/4*7850 -> 7.5202515
A28: BARRAS MACIZAS 1020 | B28: VALOR / m | C28: ULTIMA COTIZACION | D28: EMPRESA | E28: PESO POR METRO (KG)
A29: 4 ½” | B29: 340000 | C29: 42460 | D29: IMPORINOX | E29: =PI()*(4.5*0.0254)^2/4*7850 -> 80.547488
A30: 6” | B30: 550000 | C30: 2015 | D30: IMPORINOX | E30: =PI()*(6*0.0254)^2/4*7850 -> 143.19553
A31: BARRAS PERFORADAS 1518 | B31: VALOR / m | C31: ULTIMA COTIZACION | D31: EMPRESA | E31: PESO POR METRO (KG)
A32: D ext: 102 mm D in: 80 mm | B32: 112000 | C32: 42550 | D32: ACEROSCOL | E32: =(PI()*(51/1000)^2-PI()*(40/1000)^2)*7850 -> 24.686164
A33: D ext: 76 mm D in: 42 mm | B33: 112000 | C33: 42550 | D33: ACEROSCOL | E33: =(PI()*(38/1000)^2-PI()*(21/1000)^2)*7850 -> 24.735487
A34: D ext: 101 mm D in: 51 mm | B34: 212000 | C34: 42550 | D34: ACEROSCOL | E34: =(PI()*(50.5/1000)^2-PI()*(25.5/1000)^2)*7850 -> 46.856854
A35: BARRAS MACIZAS 1045 | B35: VALOR / m | C35: ULTIMA COTIZACION | D35: EMPRESA | E35: PESO POR METRO (KG)
A36: 3" | B36: 159000 | C36: 42550 | D36: ACEROSCOL | E36: =PI()*(1.5*25.4/1000)^2*7850 -> 35.798883
A37: TUBOS SCH 10 316L | B37: VALOR 5,8 m | C37: ULTIMA COTIZACION | D37: EMPRESA | E37: PESO POR METRO (KG)
A38: 1 1/4" | B38: 272600 | C38: 42579 | D38: TUVACOL | E38: =(PI()*(1.66*25.4/1000)^2-PI()*((1.66-2*0.109)*25.4/1000)^2)*7850/4 -> 2.6898326
A39: 2" | B39: =58600*5.8 -> 339880 | C39: 42550 | D39: ACEROSCOL | E39: =(PI()*(2.375*25.4/1000)^2-PI()*((2.375-2*0.109)*25.4/1000)^2)*7850/4 -> 3.9298264
A40: 3" | B40: =78000*5.8 -> 452400 | C40: 42550 | D40: ACEROSCOL | E40: =(PI()*(3.5*25.4/1000)^2-PI()*((3.5-2*0.12)*25.4/1000)^2)*7850/4 -> 6.4533454
...

Sheet P. PARTES
A1: PROPELAS
A2: COD | B2: PRECIO | C2: DESCRIPCION
A3: =P!A51 -> P2-ABM | B3: =P!D58 -> 381250 | C3: Propela Turbina 160 mm eje 1" con Manzana Acero 304SS
A4: =P!A1 -> P2-BBM | B4: =P!D8 -> 391250 | C4: Propela Turbina 200 mm eje 1" con Manzana Acero 304SS
A5: =P!A1459 -> P2-BBMS | B5: =P!D1466 -> 435200 | C5: Propela Turbina 200 mm eje 1" con Manzana Acero 316SS
A6: =P!A41 -> P2-BCM | B6: =P!D48 -> 423100 | C6: Propela Turbina 200 mm eje 1 1/4 " con Manzana Acero 304SS
A7: =P!A1542 -> P2-BCMS | B7: =P!D1549 -> 472000 | C7: Propela Turbina 200 mm eje 1 1/4 " con Manzana Acero 316SS
A8: =P!A1578 -> P2-BEC | B8: =P!D1584 -> 450000 | C8: Propela Turbina 200 mm eje 2" con Casquete 304SS
A9: =P!A1586 -> P2-BECS | B9: =P!D1592 -> 561000 | C9: Propela Turbina 200 mm eje 2" con Casquete 316SS
A10: =P!A784 -> P2-BEM | B10: =P!D791 -> 519150 | C10: Propela Turbina 200 mm eje 2" con Manzana Acero 304SS
A11: =+P!A2161 -> P2-CCM | B11: =+P!D2168 -> 458100 | C11: Propela Turbina 300 mm eje 1 1/4" con Manzana Acero 304SS
A12: =P!A1534 -> P2-CGC | B12: =P!D1540 -> 660000 | C12: Propela Turbina 300 mm eje 3" con Casquete Acero 304SS
A13: =P!A11 -> P2-DBM | B13: =P!D18 -> 441250 | C13: Propela Turbina 350 mm eje 1" con Manzana Acero 304SS
A14: =P!A21 -> P2-DCM | B14: =P!D28 -> 473100 | C14: Propela Turbina 350 mm eje 1 1/4" con Manzana Acero 304SS
A15: =P!A1551 -> P2-DCMS | B15: =P!D1558 -> 525000 | C15: Propela Turbina 350 mm eje 1 1/4" con Manzana Acero 316SS
A16: =P!A567 -> P2-DDM | B16: =P!D574 -> 433100 | C16: Propela Turbina 350 mm eje 1 1/2" con Manzana Acero 304SS
A17: =P!A1497 -> P2-DDMS | B17: =P!D1504 -> 525000 | C17: Propela Turbina 350 mm eje 1 1/2" con Manzana Acero 316SS
A18: =P!A854 -> P2-DEM | B18: =P!D861 -> 569150 | C18: Propela Turbina 350 mm eje 2" con Manzana Acero 304SS
A19: =P!A1366 -> P2-GDM | B19: =P!D1373 -> 523100 | C19: Propela Turbina 500 mm eje 1 1/2" con Manzana Acero 304SS
A20: =P!A61 -> P2-GDMS | B20: =P!D68 -> 581000 | C20: Propela Turbina 500 mm eje 1 1/2" con Manzana Acero 316SS
A21: =P!A586 -> P2-GEM | B21: =P!D593 -> 619150 | C21: Propela Turbina 500 mm eje 2" con Manzana Acero 304SS
A22: =P!A766 -> P2-GEMS | B22: =P!D773 -> 664150 | C22: Propela Turbina 500 mm eje 2" con Manzana Acero 316SS
A23: =+P!A1882 -> P2-GFC | B23: =+P!D1888 -> 580000 | C23: Propela Turbina 500 mm eje 2 1/2" con Casquete Acero 304SS
A24: =P!A961 -> P2-GFM | B24: =P!D968 -> 649150 | C24: Propela Turbina 500 mm eje 2 1/2" con Manzana Acero 304SS
A25: =P!A667 -> P2-GGC | B25: =P!D673 -> 610000 | C25: Propela Turbina 500 mm eje 3" con Casquete Acero 304SS
A26: =P!A811 -> P2-GIC | B26: =P!D817 -> 640000 | C26: Propela Turbina 500 mm eje 4" con Casquete Acero 304SS
A27: =P!A31 -> P2-HCM | B27: =P!D38 -> 563465 | C27: Propela Turbina 550 mm eje 1 1/4" con Manzana Acero 304SS
A28: =P!A1132 -> P2-HDM | B28: =P!D1139 -> 679150 | C28: Propela Turbina 550 mm eje 1 1/2" con Manzana Acero 304SS
A29: =P!A1798 -> P2-HEC | B29: =P!D1804 -> 610000 | C29: Propela Turbina 550 mm eje 2" con Casquete Acero 304SS
A30: =P!A501 -> P2-HEM | B30: =P!D508 -> 679150 | C30: Propela Turbina 550 mm eje 2" con manzana Acero 304SS
A31: =P!A952 -> P2-HFM | B31: =P!D959 -> 679150 | C31: Propela Turbina 550 mm eje 2 1/2" con manzana Acero 304SS
A32: =P!A1349 -> P2-HFMS | B32: =P!D1356 -> 730150 | C32: Propela Turbina 550 mm eje 2 1/2" con manzana Acero 316SS
A33: =P!A997 -> P2-HGC | B33: =P!D1004 -> 750000 | C33: Propela Turbina 550 mm eje 3" con Casquete Acero 304SS
A34: =P!A1630 -> P2-JDM | B34: =P!D1637 -> 779150 | C34: Propela Turbina 700 mm eje 1 1/2" con Manzana Acero 304SS
A35: =P!A121 -> P2-JEM | B35: =P!D128 -> 779150 | C35: Propela Turbina 700 mm eje 2" con Manzana Acero 304SS
A36: =P!A1171 -> P2-JFC | B36: =P!D1177 -> 740000 | C36: Propela Turbina 700 mm eje 2 1/2" con Casquete Acero 304SS
A37: =P!A151 -> P2-JGC | B37: =P!D157 -> 770000 | C37: Propela Turbina 700 mm eje 3" con Casquete Acero 304SS
A38: =P!A1179 -> P2-JIC | B38: =P!D1185 -> 800000 | C38: Propela Turbina 700 mm eje 4" con Casquete Acero 304SS
A39: =P!A1323 -> P2-JICS | B39: =P!D1329 -> 889000 | C39: Propela Turbina 700 mm eje 4" con Casquete Acero 316SS
A40: =P!A131 -> P2-KDM | B40: =P!D138 -> 763100 | C40: Propela Turbina 800 mm eje 1 1/2" con Manzana Acero 304SS
...

Sheet HERR CODS
A1: EJE | C1: ACOPLE | E1: SCHEDULE | G1: LONGITUD | I1: DIÁMETRO NOMINAL | K1: MATERIAL
C2: BRIDADO | D2: B | E2: MACIZO | F2: A | G2: XXX | I2: (3/4") | J2: A | K2: Acero A36 | L2: R
C3: DIRECTO | D3: D | E3: SCH 10 | F3: B | G3: cm | I3: (1") | J3: B | K3: Acero 316SS | L3: S
E4: SCH 40 | F4: C | I4: (1.1/4") | J4: C | K4: Acero 304SS
E5: SCH 80 | F5: D | I5: (1.1/2") | J5: D
I6: (2") | J6: E
I7: (2.1/2") | J7: F
I8: (3") | J8: G
I9: (3.1/2") | J9: H
E10: EJES | I10: (4") | J10: I
I11: (5") | J11: M
I12: (6") | J12: J
I13: (8") | J13: K
I14: (10") | J14: L
A15: AB | B15: - | C15: 2.5 | D15: - | E15: 035 | F15: - | G15: S
B18: ACOPLE BRIDADO | F18: Casillas Opcionales. Sólo serán tenidas en cuenta
F19: para una selección de material NO estándar.
A20: ACOPLE | B20: - | C20: DIAMETRO | E20: DIAMETRO | G20: MATERIAL
C21: NOMINAL | D21: - | E21: EJE | F21: -
A22: BRIDADO | C22: BRIDA | E22: MOTOREDUCTOR
C23: Hasta tres cifras. En pulgadas. | E23: Tres cifras en mm | G23: P | H23: ACERO AL CARBON PAVONADO
B24: 2" | C24: 2 | E24: 14 | F24: 014 | G24: S | H24: 316SS
B25: 2 1/2" | C25: 2.5 | E25: 18 | F25: 018 | G25: R | H25: ACERO AL CARBON
B26: 3" | C26: 3 | E26: 20 | F26: 020 | G26: Q | H26: RECUBRIMIENTO EN FIBRA DE VIDRIO | P26: 20 | Q26: 20
B27: 4" | C27: 4 | E27: 25 | F27: 025 | P27: 25 | Q27: 25
B28: 6" | C28: 6 | E28: 30 | F28: 030 | P28: 30 | Q28: 30
B29: 8" | C29: 8 | E29: 35 | F29: 035 | P29: 35 | Q29: 35
E30: 40 | F30: 040 | P30: 40 | Q30: 40
E31: 50 | F31: 050 | P31: 50 | Q31: 50
E32: 60 | F32: 060 | P32: 60 | Q32: 60
E33: 70 | F33: 070 | P33: 70 | Q33: 70
E34: 80 | F34: 080 | P34: 80 | Q34: 80
E35: 90 | F35: 090 | P35: 90 | Q35: 90
E36: 100 | F36: 100 | K36: Casilla opcional. Sólo será tenida en cuenta | P36: 100 | Q36: 100
K38: para una selección de material NO estándar.
A39: TIPO | C39: - | D39: DIÁMETRO DE PROPELA | G39: DIÁMETRO NOMINAL EJE | I39: MONTAJE | K39: MATERIAL
A40: HIPERBOLICA | B40: 1 | D40: 160 | E40: A | F40: cm | G40: (3/4") | H40: A | I40: MANZANA | J40: M | L40: A36 | M40: Acero A36 | N40: R
A41: TURBINA | B41: 2 | D41: 200 | E41: B | F41: cm | G41: (1") | H41: B | I41: CASQUETE | J41: C | L41: S6 | M41: Acero inoxidable 316SS | N41: S
A42: CURVA TRIPALA - CT | B42: 3 | D42: 300 | E42: C | F42: cm | G42: (1.1/4") | H42: C | I42: SOLDADA | J42: S | M42: Acero inoxidable 304SS
A43: GRAN CAUDAL - GC | B43: 4 | D43: 350 | E43: D | F43: cm | G43: (1.1/2") | H43: D
...

Sheet RESUMEN (2)
E3: AGITADORES TIPO TURBINA
C4: DESCRIPCION DEL EQUIPO | D4: AGITADOR | H4: MOTOR | K4: DESCRIPCION DEL EQUIPO
B5: MODELO | D5: Diam prop (mm) | E5: Long Max | F5: Peso aprox (kg) | G5: DIMENSIONES EMBALAJE (mm) | H5: POTENCIA (kW) | I5: RPM
B6: V2AB-06A137 | C6: Agitador Vertical, Propela Tipo Turbina de 200 mm de Diámetro, Longitud Maxima de Eje: 640 mm, Potencia del Motoreductor: 0,25 kW | D6: 200 | E6: 640 | F6: =L6*2 -> 42 | G6: 700*350*300 | H6: 0.25 | I6: 137 | K6: =CONCATENATE("Agitador Vertical, Propela Tipo Turbina de ",D6," mm de Diámetro, Longitud Maxima de Eje: ",E6, " mm, Potencia del Motoreductor: ",H6, " kW") -> Agitador Vertical, Propela Tipo Turbina de 200 mm de Diámetro, Longitud Maxima de Eje: 640 mm, Potencia del Motoreductor: 0,25 kW | L6: 21
B7: V2AD-09A137 | C7: Agitador Vertical, Propela Tipo Turbina de 350 mm de Diámetro, Longitud Maxima de Eje: 900 mm, Potencia del Motoreductor: 0,25 kW | D7: 350 | E7: 900 | F7: =L7*2 -> 48 | G7: 1000*450*400 | H7: 0.25 | I7: 137 | K7: =CONCATENATE("Agitador Vertical, Propela Tipo Turbina de ",D7," mm de Diámetro, Longitud Maxima de Eje: ",E7, " mm, Potencia del Motoreductor: ",H7, " kW") -> Agitador Vertical, Propela Tipo Turbina de 350 mm de Diámetro, Longitud Maxima de Eje: 900 mm, Potencia del Motoreductor: 0,25 kW | L7: 24
B8: V2AD-11C192 | C8: Agitador Vertical, Propela Tipo Turbina de 350 mm de Diámetro, Longitud Maxima de Eje: 1090 mm, Potencia del Motoreductor: 0,55 kW | D8: 350 | E8: 1090 | F8: =L8*2 -> 66 | G8: 1200*450*400 | H8: 0.55 | I8: 192 | K8: =CONCATENATE("Agitador Vertical, Propela Tipo Turbina de ",D8," mm de Diámetro, Longitud Maxima de Eje: ",E8, " mm, Potencia del Motoreductor: ",H8, " kW") -> Agitador Vertical, Propela Tipo Turbina de 350 mm de Diámetro, Longitud Maxima de Eje: 1090 mm, Potencia del Motoreductor: 0,55 kW | L8: 33
